2025-06-09 16:23:20,922 - src.processing.gemini_classifier - ERROR - File: gemini_classifier.py - File: gemini_classifier.py - File: gemini_classifier.py - File: gemini_classifier.py - File: gemini_classifier.py - Error checking approved SKU sku_da640d6c_01010101_caja_cerveza_tecate_24_piezas: '_GeneratorContextManager' object has no attribute 'query'
2025-06-09 16:23:20,925 - src.processing.batch_processor - ERROR - File: batch_processor.py - File: batch_processor.py - File: batch_processor.py - File: batch_processor.py - File: batch_processor.py - [ERROR] Failed to process sample_test.xml: '_GeneratorContextManager' object has no attribute 'close'
2025-06-09 16:23:20,955 - src.processing.batch_processor - ERROR - File: batch_processor.py - File: batch_processor.py - File: batch_processor.py - File: batch_processor.py - File: batch_processor.py - Failed to log processing result: Mapper 'Mapper[Invoice(invoices)]' has no property 'metadata'.  If this property was indicated from other mappers or configure events, ensure registry.configure() has been called.
2025-06-09 16:23:20,957 - __main__ - ERROR - File: main.py - File: main.py - File: main.py - File: main.py - File: main.py - Single file processing failed
2025-06-09 16:30:26,068 - src.processing.gemini_classifier - ERROR - File: gemini_classifier.py - File: gemini_classifier.py - File: gemini_classifier.py - File: gemini_classifier.py - File: gemini_classifier.py - Error checking approved SKU sku_141a86f5_10161506_naranja: '_GeneratorContextManager' object has no attribute 'query'
2025-06-09 16:30:26,070 - src.processing.batch_processor - ERROR - File: batch_processor.py - File: batch_processor.py - File: batch_processor.py - File: batch_processor.py - File: batch_processor.py - [ERROR] Failed to process AB31CFD1-C61A-4637-A9C0-71B7C676AAA8.xml: '_GeneratorContextManager' object has no attribute 'close'
2025-06-09 16:30:26,100 - src.processing.batch_processor - ERROR - File: batch_processor.py - File: batch_processor.py - File: batch_processor.py - File: batch_processor.py - File: batch_processor.py - Failed to log processing result: Mapper 'Mapper[Invoice(invoices)]' has no property 'metadata'.  If this property was indicated from other mappers or configure events, ensure registry.configure() has been called.
2025-06-09 16:30:26,102 - __main__ - ERROR - File: main.py - File: main.py - File: main.py - File: main.py - File: main.py - Single file processing failed
2025-06-09 16:38:05,395 - src.data.database - ERROR - File: database.py - File: database.py - File: database.py - File: database.py - File: database.py - Database session error: Mapper 'Mapper[Invoice(invoices)]' has no property 'metadata'.  If this property was indicated from other mappers or configure events, ensure registry.configure() has been called.
2025-06-09 16:38:05,397 - src.processing.gemini_classifier - ERROR - File: gemini_classifier.py - File: gemini_classifier.py - File: gemini_classifier.py - File: gemini_classifier.py - File: gemini_classifier.py - Error checking approved SKU sku_141a86f5_10161506_naranja: Mapper 'Mapper[Invoice(invoices)]' has no property 'metadata'.  If this property was indicated from other mappers or configure events, ensure registry.configure() has been called.
2025-06-09 16:38:08,409 - src.processing.gemini_classifier - ERROR - File: gemini_classifier.py - File: gemini_classifier.py - File: gemini_classifier.py - File: gemini_classifier.py - File: gemini_classifier.py - Gemini API failed after 3 attempts: Unknown field for GenerateContentRequest: request_options
2025-06-09 16:38:08,411 - src.processing.gemini_classifier - ERROR - File: gemini_classifier.py - File: gemini_classifier.py - File: gemini_classifier.py - File: gemini_classifier.py - File: gemini_classifier.py - Classification failed for sku_141a86f5_10161506_naranja: Gemini API failed after 3 attempts: Unknown field for GenerateContentRequest: request_options
2025-06-09 16:38:08,412 - src.data.database - ERROR - File: database.py - File: database.py - File: database.py - File: database.py - File: database.py - Database session error: One or more mappers failed to initialize - can't proceed with initialization of other mappers. Triggering mapper: 'Mapper[InvoiceMetadata(invoice_metadata)]'. Original exception was: Mapper 'Mapper[Invoice(invoices)]' has no property 'metadata'.  If this property was indicated from other mappers or configure events, ensure registry.configure() has been called.
2025-06-09 16:38:08,415 - src.processing.gemini_classifier - ERROR - File: gemini_classifier.py - File: gemini_classifier.py - File: gemini_classifier.py - File: gemini_classifier.py - File: gemini_classifier.py - Error checking approved SKU sku_9a57e1c2_50304100_limon_sin_semilla: One or more mappers failed to initialize - can't proceed with initialization of other mappers. Triggering mapper: 'Mapper[InvoiceMetadata(invoice_metadata)]'. Original exception was: Mapper 'Mapper[Invoice(invoices)]' has no property 'metadata'.  If this property was indicated from other mappers or configure events, ensure registry.configure() has been called.
2025-06-09 16:38:11,464 - src.processing.gemini_classifier - ERROR - File: gemini_classifier.py - File: gemini_classifier.py - File: gemini_classifier.py - File: gemini_classifier.py - File: gemini_classifier.py - Gemini API failed after 3 attempts: Unknown field for GenerateContentRequest: request_options
2025-06-09 16:38:11,472 - src.processing.gemini_classifier - ERROR - File: gemini_classifier.py - File: gemini_classifier.py - File: gemini_classifier.py - File: gemini_classifier.py - File: gemini_classifier.py - Classification failed for sku_9a57e1c2_50304100_limon_sin_semilla: Gemini API failed after 3 attempts: Unknown field for GenerateContentRequest: request_options
2025-06-09 16:38:11,479 - src.data.database - ERROR - File: database.py - File: database.py - File: database.py - File: database.py - File: database.py - Database session error: One or more mappers failed to initialize - can't proceed with initialization of other mappers. Triggering mapper: 'Mapper[InvoiceMetadata(invoice_metadata)]'. Original exception was: Mapper 'Mapper[Invoice(invoices)]' has no property 'metadata'.  If this property was indicated from other mappers or configure events, ensure registry.configure() has been called.
2025-06-09 16:38:11,488 - src.processing.gemini_classifier - ERROR - File: gemini_classifier.py - File: gemini_classifier.py - File: gemini_classifier.py - File: gemini_classifier.py - File: gemini_classifier.py - Error checking approved SKU sku_64cd09d0_50202302_hielo_bolsa_de_hielo_5kg: One or more mappers failed to initialize - can't proceed with initialization of other mappers. Triggering mapper: 'Mapper[InvoiceMetadata(invoice_metadata)]'. Original exception was: Mapper 'Mapper[Invoice(invoices)]' has no property 'metadata'.  If this property was indicated from other mappers or configure events, ensure registry.configure() has been called.
2025-06-09 16:38:14,506 - src.processing.gemini_classifier - ERROR - File: gemini_classifier.py - File: gemini_classifier.py - File: gemini_classifier.py - File: gemini_classifier.py - File: gemini_classifier.py - Gemini API failed after 3 attempts: Unknown field for GenerateContentRequest: request_options
2025-06-09 16:38:14,509 - src.processing.gemini_classifier - ERROR - File: gemini_classifier.py - File: gemini_classifier.py - File: gemini_classifier.py - File: gemini_classifier.py - File: gemini_classifier.py - Classification failed for sku_64cd09d0_50202302_hielo_bolsa_de_hielo_5kg: Gemini API failed after 3 attempts: Unknown field for GenerateContentRequest: request_options
2025-06-09 16:38:14,514 - src.data.database - ERROR - File: database.py - File: database.py - File: database.py - File: database.py - File: database.py - Database session error: One or more mappers failed to initialize - can't proceed with initialization of other mappers. Triggering mapper: 'Mapper[InvoiceMetadata(invoice_metadata)]'. Original exception was: Mapper 'Mapper[Invoice(invoices)]' has no property 'metadata'.  If this property was indicated from other mappers or configure events, ensure registry.configure() has been called.
2025-06-09 16:38:14,520 - src.processing.gemini_classifier - ERROR - File: gemini_classifier.py - File: gemini_classifier.py - File: gemini_classifier.py - File: gemini_classifier.py - File: gemini_classifier.py - Error checking approved SKU sku_6a2cfbaf_50131612_huevo_cartera_con_30pz: One or more mappers failed to initialize - can't proceed with initialization of other mappers. Triggering mapper: 'Mapper[InvoiceMetadata(invoice_metadata)]'. Original exception was: Mapper 'Mapper[Invoice(invoices)]' has no property 'metadata'.  If this property was indicated from other mappers or configure events, ensure registry.configure() has been called.
2025-06-09 16:38:17,536 - src.processing.gemini_classifier - ERROR - File: gemini_classifier.py - File: gemini_classifier.py - File: gemini_classifier.py - File: gemini_classifier.py - File: gemini_classifier.py - Gemini API failed after 3 attempts: Unknown field for GenerateContentRequest: request_options
2025-06-09 16:38:17,538 - src.processing.gemini_classifier - ERROR - File: gemini_classifier.py - File: gemini_classifier.py - File: gemini_classifier.py - File: gemini_classifier.py - File: gemini_classifier.py - Classification failed for sku_6a2cfbaf_50131612_huevo_cartera_con_30pz: Gemini API failed after 3 attempts: Unknown field for GenerateContentRequest: request_options
2025-06-09 16:38:17,541 - src.data.database - ERROR - File: database.py - File: database.py - File: database.py - File: database.py - File: database.py - Database session error: One or more mappers failed to initialize - can't proceed with initialization of other mappers. Triggering mapper: 'Mapper[InvoiceMetadata(invoice_metadata)]'. Original exception was: Mapper 'Mapper[Invoice(invoices)]' has no property 'metadata'.  If this property was indicated from other mappers or configure events, ensure registry.configure() has been called.
2025-06-09 16:38:17,549 - src.processing.gemini_classifier - ERROR - File: gemini_classifier.py - File: gemini_classifier.py - File: gemini_classifier.py - File: gemini_classifier.py - File: gemini_classifier.py - Error checking approved SKU sku_3823c19d_50405300_cebolla_blanca: One or more mappers failed to initialize - can't proceed with initialization of other mappers. Triggering mapper: 'Mapper[InvoiceMetadata(invoice_metadata)]'. Original exception was: Mapper 'Mapper[Invoice(invoices)]' has no property 'metadata'.  If this property was indicated from other mappers or configure events, ensure registry.configure() has been called.
2025-06-09 16:38:20,565 - src.processing.gemini_classifier - ERROR - File: gemini_classifier.py - File: gemini_classifier.py - File: gemini_classifier.py - File: gemini_classifier.py - File: gemini_classifier.py - Gemini API failed after 3 attempts: Unknown field for GenerateContentRequest: request_options
2025-06-09 16:38:20,568 - src.processing.gemini_classifier - ERROR - File: gemini_classifier.py - File: gemini_classifier.py - File: gemini_classifier.py - File: gemini_classifier.py - File: gemini_classifier.py - Classification failed for sku_3823c19d_50405300_cebolla_blanca: Gemini API failed after 3 attempts: Unknown field for GenerateContentRequest: request_options
2025-06-09 16:38:20,574 - src.data.database - ERROR - File: database.py - File: database.py - File: database.py - File: database.py - File: database.py - Database session error: One or more mappers failed to initialize - can't proceed with initialization of other mappers. Triggering mapper: 'Mapper[InvoiceMetadata(invoice_metadata)]'. Original exception was: Mapper 'Mapper[Invoice(invoices)]' has no property 'metadata'.  If this property was indicated from other mappers or configure events, ensure registry.configure() has been called.
2025-06-09 16:38:20,582 - src.processing.gemini_classifier - ERROR - File: gemini_classifier.py - File: gemini_classifier.py - File: gemini_classifier.py - File: gemini_classifier.py - File: gemini_classifier.py - Error checking approved SKU sku_65d00f8a_50404101_albahaca: One or more mappers failed to initialize - can't proceed with initialization of other mappers. Triggering mapper: 'Mapper[InvoiceMetadata(invoice_metadata)]'. Original exception was: Mapper 'Mapper[Invoice(invoices)]' has no property 'metadata'.  If this property was indicated from other mappers or configure events, ensure registry.configure() has been called.
2025-06-09 16:38:23,596 - src.processing.gemini_classifier - ERROR - File: gemini_classifier.py - File: gemini_classifier.py - File: gemini_classifier.py - File: gemini_classifier.py - File: gemini_classifier.py - Gemini API failed after 3 attempts: Unknown field for GenerateContentRequest: request_options
2025-06-09 16:38:23,600 - src.processing.gemini_classifier - ERROR - File: gemini_classifier.py - File: gemini_classifier.py - File: gemini_classifier.py - File: gemini_classifier.py - File: gemini_classifier.py - Classification failed for sku_65d00f8a_50404101_albahaca: Gemini API failed after 3 attempts: Unknown field for GenerateContentRequest: request_options
2025-06-09 16:38:23,605 - src.data.database - ERROR - File: database.py - File: database.py - File: database.py - File: database.py - File: database.py - Database session error: One or more mappers failed to initialize - can't proceed with initialization of other mappers. Triggering mapper: 'Mapper[InvoiceMetadata(invoice_metadata)]'. Original exception was: Mapper 'Mapper[Invoice(invoices)]' has no property 'metadata'.  If this property was indicated from other mappers or configure events, ensure registry.configure() has been called.
2025-06-09 16:38:23,610 - src.processing.gemini_classifier - ERROR - File: gemini_classifier.py - File: gemini_classifier.py - File: gemini_classifier.py - File: gemini_classifier.py - File: gemini_classifier.py - Error checking approved SKU sku_44f0bbec_50403900_calabaza_negra: One or more mappers failed to initialize - can't proceed with initialization of other mappers. Triggering mapper: 'Mapper[InvoiceMetadata(invoice_metadata)]'. Original exception was: Mapper 'Mapper[Invoice(invoices)]' has no property 'metadata'.  If this property was indicated from other mappers or configure events, ensure registry.configure() has been called.
2025-06-09 16:38:26,623 - src.processing.gemini_classifier - ERROR - File: gemini_classifier.py - File: gemini_classifier.py - File: gemini_classifier.py - File: gemini_classifier.py - File: gemini_classifier.py - Gemini API failed after 3 attempts: Unknown field for GenerateContentRequest: request_options
2025-06-09 16:38:26,626 - src.processing.gemini_classifier - ERROR - File: gemini_classifier.py - File: gemini_classifier.py - File: gemini_classifier.py - File: gemini_classifier.py - File: gemini_classifier.py - Classification failed for sku_44f0bbec_50403900_calabaza_negra: Gemini API failed after 3 attempts: Unknown field for GenerateContentRequest: request_options
2025-06-09 16:38:26,628 - src.data.database - ERROR - File: database.py - File: database.py - File: database.py - File: database.py - File: database.py - Database session error: One or more mappers failed to initialize - can't proceed with initialization of other mappers. Triggering mapper: 'Mapper[InvoiceMetadata(invoice_metadata)]'. Original exception was: Mapper 'Mapper[Invoice(invoices)]' has no property 'metadata'.  If this property was indicated from other mappers or configure events, ensure registry.configure() has been called.
2025-06-09 16:38:26,631 - src.processing.gemini_classifier - ERROR - File: gemini_classifier.py - File: gemini_classifier.py - File: gemini_classifier.py - File: gemini_classifier.py - File: gemini_classifier.py - Error checking approved SKU sku_9694c503_50403500_berenjena: One or more mappers failed to initialize - can't proceed with initialization of other mappers. Triggering mapper: 'Mapper[InvoiceMetadata(invoice_metadata)]'. Original exception was: Mapper 'Mapper[Invoice(invoices)]' has no property 'metadata'.  If this property was indicated from other mappers or configure events, ensure registry.configure() has been called.
2025-06-09 16:38:29,646 - src.processing.gemini_classifier - ERROR - File: gemini_classifier.py - File: gemini_classifier.py - File: gemini_classifier.py - File: gemini_classifier.py - File: gemini_classifier.py - Gemini API failed after 3 attempts: Unknown field for GenerateContentRequest: request_options
2025-06-09 16:38:29,647 - src.processing.gemini_classifier - ERROR - File: gemini_classifier.py - File: gemini_classifier.py - File: gemini_classifier.py - File: gemini_classifier.py - File: gemini_classifier.py - Classification failed for sku_9694c503_50403500_berenjena: Gemini API failed after 3 attempts: Unknown field for GenerateContentRequest: request_options
2025-06-09 16:38:29,655 - src.data.database - ERROR - File: database.py - File: database.py - File: database.py - File: database.py - File: database.py - Database session error: One or more mappers failed to initialize - can't proceed with initialization of other mappers. Triggering mapper: 'Mapper[InvoiceMetadata(invoice_metadata)]'. Original exception was: Mapper 'Mapper[Invoice(invoices)]' has no property 'metadata'.  If this property was indicated from other mappers or configure events, ensure registry.configure() has been called.
2025-06-09 16:38:29,657 - src.processing.gemini_classifier - ERROR - File: gemini_classifier.py - File: gemini_classifier.py - File: gemini_classifier.py - File: gemini_classifier.py - File: gemini_classifier.py - Error checking approved SKU sku_09573e71_50417006_arugula: One or more mappers failed to initialize - can't proceed with initialization of other mappers. Triggering mapper: 'Mapper[InvoiceMetadata(invoice_metadata)]'. Original exception was: Mapper 'Mapper[Invoice(invoices)]' has no property 'metadata'.  If this property was indicated from other mappers or configure events, ensure registry.configure() has been called.
2025-06-09 16:38:32,668 - src.processing.gemini_classifier - ERROR - File: gemini_classifier.py - File: gemini_classifier.py - File: gemini_classifier.py - File: gemini_classifier.py - File: gemini_classifier.py - Gemini API failed after 3 attempts: Unknown field for GenerateContentRequest: request_options
2025-06-09 16:38:32,670 - src.processing.gemini_classifier - ERROR - File: gemini_classifier.py - File: gemini_classifier.py - File: gemini_classifier.py - File: gemini_classifier.py - File: gemini_classifier.py - Classification failed for sku_09573e71_50417006_arugula: Gemini API failed after 3 attempts: Unknown field for GenerateContentRequest: request_options
2025-06-09 16:38:32,672 - src.data.database - ERROR - File: database.py - File: database.py - File: database.py - File: database.py - File: database.py - Database session error: One or more mappers failed to initialize - can't proceed with initialization of other mappers. Triggering mapper: 'Mapper[InvoiceMetadata(invoice_metadata)]'. Original exception was: Mapper 'Mapper[Invoice(invoices)]' has no property 'metadata'.  If this property was indicated from other mappers or configure events, ensure registry.configure() has been called.
2025-06-09 16:38:32,676 - src.processing.gemini_classifier - ERROR - File: gemini_classifier.py - File: gemini_classifier.py - File: gemini_classifier.py - File: gemini_classifier.py - File: gemini_classifier.py - Error checking approved SKU sku_6a416cf3_50131800_queso_fresco: One or more mappers failed to initialize - can't proceed with initialization of other mappers. Triggering mapper: 'Mapper[InvoiceMetadata(invoice_metadata)]'. Original exception was: Mapper 'Mapper[Invoice(invoices)]' has no property 'metadata'.  If this property was indicated from other mappers or configure events, ensure registry.configure() has been called.
2025-06-09 16:38:35,687 - src.processing.gemini_classifier - ERROR - File: gemini_classifier.py - File: gemini_classifier.py - File: gemini_classifier.py - File: gemini_classifier.py - File: gemini_classifier.py - Gemini API failed after 3 attempts: Unknown field for GenerateContentRequest: request_options
2025-06-09 16:38:35,688 - src.processing.gemini_classifier - ERROR - File: gemini_classifier.py - File: gemini_classifier.py - File: gemini_classifier.py - File: gemini_classifier.py - File: gemini_classifier.py - Classification failed for sku_6a416cf3_50131800_queso_fresco: Gemini API failed after 3 attempts: Unknown field for GenerateContentRequest: request_options
2025-06-09 16:38:35,691 - src.data.database - ERROR - File: database.py - File: database.py - File: database.py - File: database.py - File: database.py - Database session error: One or more mappers failed to initialize - can't proceed with initialization of other mappers. Triggering mapper: 'Mapper[InvoiceMetadata(invoice_metadata)]'. Original exception was: Mapper 'Mapper[Invoice(invoices)]' has no property 'metadata'.  If this property was indicated from other mappers or configure events, ensure registry.configure() has been called.
2025-06-09 16:38:35,697 - src.processing.gemini_classifier - ERROR - File: gemini_classifier.py - File: gemini_classifier.py - File: gemini_classifier.py - File: gemini_classifier.py - File: gemini_classifier.py - Error checking approved SKU sku_2df84722_50221001_arroz_verde_valle_500gr: One or more mappers failed to initialize - can't proceed with initialization of other mappers. Triggering mapper: 'Mapper[InvoiceMetadata(invoice_metadata)]'. Original exception was: Mapper 'Mapper[Invoice(invoices)]' has no property 'metadata'.  If this property was indicated from other mappers or configure events, ensure registry.configure() has been called.
2025-06-09 16:38:38,710 - src.processing.gemini_classifier - ERROR - File: gemini_classifier.py - File: gemini_classifier.py - File: gemini_classifier.py - File: gemini_classifier.py - File: gemini_classifier.py - Gemini API failed after 3 attempts: Unknown field for GenerateContentRequest: request_options
2025-06-09 16:38:38,713 - src.processing.gemini_classifier - ERROR - File: gemini_classifier.py - File: gemini_classifier.py - File: gemini_classifier.py - File: gemini_classifier.py - File: gemini_classifier.py - Classification failed for sku_2df84722_50221001_arroz_verde_valle_500gr: Gemini API failed after 3 attempts: Unknown field for GenerateContentRequest: request_options
2025-06-09 16:38:38,717 - src.data.database - ERROR - File: database.py - File: database.py - File: database.py - File: database.py - File: database.py - Database session error: One or more mappers failed to initialize - can't proceed with initialization of other mappers. Triggering mapper: 'Mapper[InvoiceMetadata(invoice_metadata)]'. Original exception was: Mapper 'Mapper[Invoice(invoices)]' has no property 'metadata'.  If this property was indicated from other mappers or configure events, ensure registry.configure() has been called.
2025-06-09 16:38:38,719 - src.processing.gemini_classifier - ERROR - File: gemini_classifier.py - File: gemini_classifier.py - File: gemini_classifier.py - File: gemini_classifier.py - File: gemini_classifier.py - Error checking approved SKU sku_c0496069_50406500_tomate_salades: One or more mappers failed to initialize - can't proceed with initialization of other mappers. Triggering mapper: 'Mapper[InvoiceMetadata(invoice_metadata)]'. Original exception was: Mapper 'Mapper[Invoice(invoices)]' has no property 'metadata'.  If this property was indicated from other mappers or configure events, ensure registry.configure() has been called.
2025-06-09 16:38:41,731 - src.processing.gemini_classifier - ERROR - File: gemini_classifier.py - File: gemini_classifier.py - File: gemini_classifier.py - File: gemini_classifier.py - File: gemini_classifier.py - Gemini API failed after 3 attempts: Unknown field for GenerateContentRequest: request_options
2025-06-09 16:38:41,733 - src.processing.gemini_classifier - ERROR - File: gemini_classifier.py - File: gemini_classifier.py - File: gemini_classifier.py - File: gemini_classifier.py - File: gemini_classifier.py - Classification failed for sku_c0496069_50406500_tomate_salades: Gemini API failed after 3 attempts: Unknown field for GenerateContentRequest: request_options
2025-06-09 16:38:41,735 - src.data.database - ERROR - File: database.py - File: database.py - File: database.py - File: database.py - File: database.py - Database session error: One or more mappers failed to initialize - can't proceed with initialization of other mappers. Triggering mapper: 'Mapper[InvoiceMetadata(invoice_metadata)]'. Original exception was: Mapper 'Mapper[Invoice(invoices)]' has no property 'metadata'.  If this property was indicated from other mappers or configure events, ensure registry.configure() has been called.
2025-06-09 16:38:41,739 - src.processing.gemini_classifier - ERROR - File: gemini_classifier.py - File: gemini_classifier.py - File: gemini_classifier.py - File: gemini_classifier.py - File: gemini_classifier.py - Error checking approved SKU sku_11cd495e_50401700_aguacate: One or more mappers failed to initialize - can't proceed with initialization of other mappers. Triggering mapper: 'Mapper[InvoiceMetadata(invoice_metadata)]'. Original exception was: Mapper 'Mapper[Invoice(invoices)]' has no property 'metadata'.  If this property was indicated from other mappers or configure events, ensure registry.configure() has been called.
2025-06-09 16:38:44,752 - src.processing.gemini_classifier - ERROR - File: gemini_classifier.py - File: gemini_classifier.py - File: gemini_classifier.py - File: gemini_classifier.py - File: gemini_classifier.py - Gemini API failed after 3 attempts: Unknown field for GenerateContentRequest: request_options
2025-06-09 16:38:44,756 - src.processing.gemini_classifier - ERROR - File: gemini_classifier.py - File: gemini_classifier.py - File: gemini_classifier.py - File: gemini_classifier.py - File: gemini_classifier.py - Classification failed for sku_11cd495e_50401700_aguacate: Gemini API failed after 3 attempts: Unknown field for GenerateContentRequest: request_options
2025-06-09 16:38:44,763 - src.data.database - ERROR - File: database.py - File: database.py - File: database.py - File: database.py - File: database.py - Database session error: One or more mappers failed to initialize - can't proceed with initialization of other mappers. Triggering mapper: 'Mapper[InvoiceMetadata(invoice_metadata)]'. Original exception was: Mapper 'Mapper[Invoice(invoices)]' has no property 'metadata'.  If this property was indicated from other mappers or configure events, ensure registry.configure() has been called.
2025-06-09 16:38:44,769 - src.processing.gemini_classifier - ERROR - File: gemini_classifier.py - File: gemini_classifier.py - File: gemini_classifier.py - File: gemini_classifier.py - File: gemini_classifier.py - Error checking approved SKU sku_ac43b4be_27112003_rastrillo: One or more mappers failed to initialize - can't proceed with initialization of other mappers. Triggering mapper: 'Mapper[InvoiceMetadata(invoice_metadata)]'. Original exception was: Mapper 'Mapper[Invoice(invoices)]' has no property 'metadata'.  If this property was indicated from other mappers or configure events, ensure registry.configure() has been called.
2025-06-09 16:38:47,794 - src.processing.gemini_classifier - ERROR - File: gemini_classifier.py - File: gemini_classifier.py - File: gemini_classifier.py - File: gemini_classifier.py - File: gemini_classifier.py - Gemini API failed after 3 attempts: Unknown field for GenerateContentRequest: request_options
2025-06-09 16:38:47,796 - src.processing.gemini_classifier - ERROR - File: gemini_classifier.py - File: gemini_classifier.py - File: gemini_classifier.py - File: gemini_classifier.py - File: gemini_classifier.py - Classification failed for sku_ac43b4be_27112003_rastrillo: Gemini API failed after 3 attempts: Unknown field for GenerateContentRequest: request_options
2025-06-09 16:38:47,806 - src.data.database - ERROR - File: database.py - File: database.py - File: database.py - File: database.py - File: database.py - Database session error: One or more mappers failed to initialize - can't proceed with initialization of other mappers. Triggering mapper: 'Mapper[InvoiceMetadata(invoice_metadata)]'. Original exception was: Mapper 'Mapper[Invoice(invoices)]' has no property 'metadata'.  If this property was indicated from other mappers or configure events, ensure registry.configure() has been called.
2025-06-09 16:38:47,814 - src.processing.gemini_classifier - ERROR - File: gemini_classifier.py - File: gemini_classifier.py - File: gemini_classifier.py - File: gemini_classifier.py - File: gemini_classifier.py - Error checking approved SKU sku_6a2cfbaf_50131612_huevo_cartera_con_30pz: One or more mappers failed to initialize - can't proceed with initialization of other mappers. Triggering mapper: 'Mapper[InvoiceMetadata(invoice_metadata)]'. Original exception was: Mapper 'Mapper[Invoice(invoices)]' has no property 'metadata'.  If this property was indicated from other mappers or configure events, ensure registry.configure() has been called.
2025-06-09 16:38:50,833 - src.processing.gemini_classifier - ERROR - File: gemini_classifier.py - File: gemini_classifier.py - File: gemini_classifier.py - File: gemini_classifier.py - File: gemini_classifier.py - Gemini API failed after 3 attempts: Unknown field for GenerateContentRequest: request_options
2025-06-09 16:38:50,835 - src.processing.gemini_classifier - ERROR - File: gemini_classifier.py - File: gemini_classifier.py - File: gemini_classifier.py - File: gemini_classifier.py - File: gemini_classifier.py - Classification failed for sku_6a2cfbaf_50131612_huevo_cartera_con_30pz: Gemini API failed after 3 attempts: Unknown field for GenerateContentRequest: request_options
2025-06-09 16:38:50,839 - src.data.database - ERROR - File: database.py - File: database.py - File: database.py - File: database.py - File: database.py - Database session error: One or more mappers failed to initialize - can't proceed with initialization of other mappers. Triggering mapper: 'Mapper[InvoiceMetadata(invoice_metadata)]'. Original exception was: Mapper 'Mapper[Invoice(invoices)]' has no property 'metadata'.  If this property was indicated from other mappers or configure events, ensure registry.configure() has been called.
2025-06-09 16:38:50,840 - src.processing.gemini_classifier - ERROR - File: gemini_classifier.py - File: gemini_classifier.py - File: gemini_classifier.py - File: gemini_classifier.py - File: gemini_classifier.py - Error checking approved SKU sku_d71b9f5d_52152200_fibra: One or more mappers failed to initialize - can't proceed with initialization of other mappers. Triggering mapper: 'Mapper[InvoiceMetadata(invoice_metadata)]'. Original exception was: Mapper 'Mapper[Invoice(invoices)]' has no property 'metadata'.  If this property was indicated from other mappers or configure events, ensure registry.configure() has been called.
2025-06-09 16:38:53,850 - src.processing.gemini_classifier - ERROR - File: gemini_classifier.py - File: gemini_classifier.py - File: gemini_classifier.py - File: gemini_classifier.py - File: gemini_classifier.py - Gemini API failed after 3 attempts: Unknown field for GenerateContentRequest: request_options
2025-06-09 16:38:53,852 - src.processing.gemini_classifier - ERROR - File: gemini_classifier.py - File: gemini_classifier.py - File: gemini_classifier.py - File: gemini_classifier.py - File: gemini_classifier.py - Classification failed for sku_d71b9f5d_52152200_fibra: Gemini API failed after 3 attempts: Unknown field for GenerateContentRequest: request_options
2025-06-09 16:38:53,855 - src.data.database - ERROR - File: database.py - File: database.py - File: database.py - File: database.py - File: database.py - Database session error: [<class 'decimal.ConversionSyntax'>]
2025-06-09 16:38:53,856 - src.processing.batch_processor - ERROR - File: batch_processor.py - File: batch_processor.py - File: batch_processor.py - File: batch_processor.py - File: batch_processor.py - Database save failed: [<class 'decimal.ConversionSyntax'>]
2025-06-09 16:38:53,857 - src.processing.batch_processor - ERROR - File: batch_processor.py - File: batch_processor.py - File: batch_processor.py - File: batch_processor.py - File: batch_processor.py - [ERROR] Failed to process AB31CFD1-C61A-4637-A9C0-71B7C676AAA8.xml: Failed to save invoice to database
2025-06-09 16:38:53,859 - src.data.database - ERROR - File: database.py - File: database.py - File: database.py - File: database.py - File: database.py - Database session error: One or more mappers failed to initialize - can't proceed with initialization of other mappers. Triggering mapper: 'Mapper[InvoiceMetadata(invoice_metadata)]'. Original exception was: Mapper 'Mapper[Invoice(invoices)]' has no property 'metadata'.  If this property was indicated from other mappers or configure events, ensure registry.configure() has been called.
2025-06-09 16:38:53,862 - src.processing.batch_processor - ERROR - File: batch_processor.py - File: batch_processor.py - File: batch_processor.py - File: batch_processor.py - File: batch_processor.py - Failed to log processing result: One or more mappers failed to initialize - can't proceed with initialization of other mappers. Triggering mapper: 'Mapper[InvoiceMetadata(invoice_metadata)]'. Original exception was: Mapper 'Mapper[Invoice(invoices)]' has no property 'metadata'.  If this property was indicated from other mappers or configure events, ensure registry.configure() has been called.
2025-06-09 16:38:53,884 - src.data.database - ERROR - File: database.py - File: database.py - File: database.py - File: database.py - File: database.py - Database session error: One or more mappers failed to initialize - can't proceed with initialization of other mappers. Triggering mapper: 'Mapper[InvoiceMetadata(invoice_metadata)]'. Original exception was: Mapper 'Mapper[Invoice(invoices)]' has no property 'metadata'.  If this property was indicated from other mappers or configure events, ensure registry.configure() has been called.
2025-06-09 16:38:53,886 - src.processing.gemini_classifier - ERROR - File: gemini_classifier.py - File: gemini_classifier.py - File: gemini_classifier.py - File: gemini_classifier.py - File: gemini_classifier.py - Error checking approved SKU sku_da640d6c_01010101_caja_cerveza_tecate_24_piezas: One or more mappers failed to initialize - can't proceed with initialization of other mappers. Triggering mapper: 'Mapper[InvoiceMetadata(invoice_metadata)]'. Original exception was: Mapper 'Mapper[Invoice(invoices)]' has no property 'metadata'.  If this property was indicated from other mappers or configure events, ensure registry.configure() has been called.
2025-06-09 16:38:56,920 - src.processing.gemini_classifier - ERROR - File: gemini_classifier.py - File: gemini_classifier.py - File: gemini_classifier.py - File: gemini_classifier.py - File: gemini_classifier.py - Gemini API failed after 3 attempts: Unknown field for GenerateContentRequest: request_options
2025-06-09 16:38:56,922 - src.processing.gemini_classifier - ERROR - File: gemini_classifier.py - File: gemini_classifier.py - File: gemini_classifier.py - File: gemini_classifier.py - File: gemini_classifier.py - Classification failed for sku_da640d6c_01010101_caja_cerveza_tecate_24_piezas: Gemini API failed after 3 attempts: Unknown field for GenerateContentRequest: request_options
2025-06-09 16:38:56,926 - src.data.database - ERROR - File: database.py - File: database.py - File: database.py - File: database.py - File: database.py - Database session error: One or more mappers failed to initialize - can't proceed with initialization of other mappers. Triggering mapper: 'Mapper[InvoiceMetadata(invoice_metadata)]'. Original exception was: Mapper 'Mapper[Invoice(invoices)]' has no property 'metadata'.  If this property was indicated from other mappers or configure events, ensure registry.configure() has been called.
2025-06-09 16:38:56,931 - src.processing.gemini_classifier - ERROR - File: gemini_classifier.py - File: gemini_classifier.py - File: gemini_classifier.py - File: gemini_classifier.py - File: gemini_classifier.py - Error checking approved SKU sku_c7a4b12e_01010102_cebolla_blanca: One or more mappers failed to initialize - can't proceed with initialization of other mappers. Triggering mapper: 'Mapper[InvoiceMetadata(invoice_metadata)]'. Original exception was: Mapper 'Mapper[Invoice(invoices)]' has no property 'metadata'.  If this property was indicated from other mappers or configure events, ensure registry.configure() has been called.
2025-06-09 16:38:59,939 - src.processing.gemini_classifier - ERROR - File: gemini_classifier.py - File: gemini_classifier.py - File: gemini_classifier.py - File: gemini_classifier.py - File: gemini_classifier.py - Gemini API failed after 3 attempts: Unknown field for GenerateContentRequest: request_options
2025-06-09 16:38:59,942 - src.processing.gemini_classifier - ERROR - File: gemini_classifier.py - File: gemini_classifier.py - File: gemini_classifier.py - File: gemini_classifier.py - File: gemini_classifier.py - Classification failed for sku_c7a4b12e_01010102_cebolla_blanca: Gemini API failed after 3 attempts: Unknown field for GenerateContentRequest: request_options
2025-06-09 16:38:59,947 - src.data.database - ERROR - File: database.py - File: database.py - File: database.py - File: database.py - File: database.py - Database session error: One or more mappers failed to initialize - can't proceed with initialization of other mappers. Triggering mapper: 'Mapper[InvoiceMetadata(invoice_metadata)]'. Original exception was: Mapper 'Mapper[Invoice(invoices)]' has no property 'metadata'.  If this property was indicated from other mappers or configure events, ensure registry.configure() has been called.
2025-06-09 16:38:59,949 - src.processing.gemini_classifier - ERROR - File: gemini_classifier.py - File: gemini_classifier.py - File: gemini_classifier.py - File: gemini_classifier.py - File: gemini_classifier.py - Error checking approved SKU sku_da1ad129_01010103_huevos_blancos_paquete_12_piezas: One or more mappers failed to initialize - can't proceed with initialization of other mappers. Triggering mapper: 'Mapper[InvoiceMetadata(invoice_metadata)]'. Original exception was: Mapper 'Mapper[Invoice(invoices)]' has no property 'metadata'.  If this property was indicated from other mappers or configure events, ensure registry.configure() has been called.
2025-06-09 16:39:02,958 - src.processing.gemini_classifier - ERROR - File: gemini_classifier.py - File: gemini_classifier.py - File: gemini_classifier.py - File: gemini_classifier.py - File: gemini_classifier.py - Gemini API failed after 3 attempts: Unknown field for GenerateContentRequest: request_options
2025-06-09 16:39:02,959 - src.processing.gemini_classifier - ERROR - File: gemini_classifier.py - File: gemini_classifier.py - File: gemini_classifier.py - File: gemini_classifier.py - File: gemini_classifier.py - Classification failed for sku_da1ad129_01010103_huevos_blancos_paquete_12_piezas: Gemini API failed after 3 attempts: Unknown field for GenerateContentRequest: request_options
2025-06-09 16:39:02,961 - src.data.database - ERROR - File: database.py - File: database.py - File: database.py - File: database.py - File: database.py - Database session error: One or more mappers failed to initialize - can't proceed with initialization of other mappers. Triggering mapper: 'Mapper[InvoiceMetadata(invoice_metadata)]'. Original exception was: Mapper 'Mapper[Invoice(invoices)]' has no property 'metadata'.  If this property was indicated from other mappers or configure events, ensure registry.configure() has been called.
2025-06-09 16:39:02,963 - src.processing.gemini_classifier - ERROR - File: gemini_classifier.py - File: gemini_classifier.py - File: gemini_classifier.py - File: gemini_classifier.py - File: gemini_classifier.py - Error checking approved SKU sku_804563e4_01010104_aceite_vegetal_1_litro: One or more mappers failed to initialize - can't proceed with initialization of other mappers. Triggering mapper: 'Mapper[InvoiceMetadata(invoice_metadata)]'. Original exception was: Mapper 'Mapper[Invoice(invoices)]' has no property 'metadata'.  If this property was indicated from other mappers or configure events, ensure registry.configure() has been called.
2025-06-09 16:39:05,993 - src.processing.gemini_classifier - ERROR - File: gemini_classifier.py - File: gemini_classifier.py - File: gemini_classifier.py - File: gemini_classifier.py - File: gemini_classifier.py - Gemini API failed after 3 attempts: Unknown field for GenerateContentRequest: request_options
2025-06-09 16:39:05,993 - src.processing.gemini_classifier - ERROR - File: gemini_classifier.py - File: gemini_classifier.py - File: gemini_classifier.py - File: gemini_classifier.py - File: gemini_classifier.py - Classification failed for sku_804563e4_01010104_aceite_vegetal_1_litro: Gemini API failed after 3 attempts: Unknown field for GenerateContentRequest: request_options
2025-06-09 16:39:05,995 - src.data.database - ERROR - File: database.py - File: database.py - File: database.py - File: database.py - File: database.py - Database session error: One or more mappers failed to initialize - can't proceed with initialization of other mappers. Triggering mapper: 'Mapper[InvoiceMetadata(invoice_metadata)]'. Original exception was: Mapper 'Mapper[Invoice(invoices)]' has no property 'metadata'.  If this property was indicated from other mappers or configure events, ensure registry.configure() has been called.
2025-06-09 16:39:05,996 - src.processing.gemini_classifier - ERROR - File: gemini_classifier.py - File: gemini_classifier.py - File: gemini_classifier.py - File: gemini_classifier.py - File: gemini_classifier.py - Error checking approved SKU sku_530c4adf_80161500_servicio_de_entrega: One or more mappers failed to initialize - can't proceed with initialization of other mappers. Triggering mapper: 'Mapper[InvoiceMetadata(invoice_metadata)]'. Original exception was: Mapper 'Mapper[Invoice(invoices)]' has no property 'metadata'.  If this property was indicated from other mappers or configure events, ensure registry.configure() has been called.
2025-06-09 16:39:09,006 - src.processing.gemini_classifier - ERROR - File: gemini_classifier.py - File: gemini_classifier.py - File: gemini_classifier.py - File: gemini_classifier.py - File: gemini_classifier.py - Gemini API failed after 3 attempts: Unknown field for GenerateContentRequest: request_options
2025-06-09 16:39:09,007 - src.processing.gemini_classifier - ERROR - File: gemini_classifier.py - File: gemini_classifier.py - File: gemini_classifier.py - File: gemini_classifier.py - File: gemini_classifier.py - Classification failed for sku_530c4adf_80161500_servicio_de_entrega: Gemini API failed after 3 attempts: Unknown field for GenerateContentRequest: request_options
2025-06-09 16:39:09,011 - src.data.database - ERROR - File: database.py - File: database.py - File: database.py - File: database.py - File: database.py - Database session error: One or more mappers failed to initialize - can't proceed with initialization of other mappers. Triggering mapper: 'Mapper[InvoiceMetadata(invoice_metadata)]'. Original exception was: Mapper 'Mapper[Invoice(invoices)]' has no property 'metadata'.  If this property was indicated from other mappers or configure events, ensure registry.configure() has been called.
2025-06-09 16:39:09,012 - src.processing.batch_processor - ERROR - File: batch_processor.py - File: batch_processor.py - File: batch_processor.py - File: batch_processor.py - File: batch_processor.py - Database save failed: One or more mappers failed to initialize - can't proceed with initialization of other mappers. Triggering mapper: 'Mapper[InvoiceMetadata(invoice_metadata)]'. Original exception was: Mapper 'Mapper[Invoice(invoices)]' has no property 'metadata'.  If this property was indicated from other mappers or configure events, ensure registry.configure() has been called.
2025-06-09 16:39:09,015 - src.processing.batch_processor - ERROR - File: batch_processor.py - File: batch_processor.py - File: batch_processor.py - File: batch_processor.py - File: batch_processor.py - [ERROR] Failed to process sample_test.xml: Failed to save invoice to database
2025-06-09 16:39:09,019 - src.data.database - ERROR - File: database.py - File: database.py - File: database.py - File: database.py - File: database.py - Database session error: One or more mappers failed to initialize - can't proceed with initialization of other mappers. Triggering mapper: 'Mapper[InvoiceMetadata(invoice_metadata)]'. Original exception was: Mapper 'Mapper[Invoice(invoices)]' has no property 'metadata'.  If this property was indicated from other mappers or configure events, ensure registry.configure() has been called.
2025-06-09 16:39:09,022 - src.processing.batch_processor - ERROR - File: batch_processor.py - File: batch_processor.py - File: batch_processor.py - File: batch_processor.py - File: batch_processor.py - Failed to log processing result: One or more mappers failed to initialize - can't proceed with initialization of other mappers. Triggering mapper: 'Mapper[InvoiceMetadata(invoice_metadata)]'. Original exception was: Mapper 'Mapper[Invoice(invoices)]' has no property 'metadata'.  If this property was indicated from other mappers or configure events, ensure registry.configure() has been called.
2025-06-09 16:41:01,657 - src.data.database - ERROR - File: database.py - File: database.py - File: database.py - File: database.py - File: database.py - Database session error: [<class 'decimal.ConversionSyntax'>]
2025-06-09 16:41:01,659 - src.processing.batch_processor - ERROR - File: batch_processor.py - File: batch_processor.py - File: batch_processor.py - File: batch_processor.py - File: batch_processor.py - Database save failed: [<class 'decimal.ConversionSyntax'>]
2025-06-09 16:41:01,660 - src.processing.batch_processor - ERROR - File: batch_processor.py - File: batch_processor.py - File: batch_processor.py - File: batch_processor.py - File: batch_processor.py - [ERROR] Failed to process AB31CFD1-C61A-4637-A9C0-71B7C676AAA8.xml: Failed to save invoice to database
2025-06-09 16:42:49,696 - src.data.database - ERROR - File: database.py - File: database.py - File: database.py - File: database.py - File: database.py - Database session error: [<class 'decimal.ConversionSyntax'>]
2025-06-09 16:42:49,699 - src.processing.batch_processor - ERROR - File: batch_processor.py - File: batch_processor.py - File: batch_processor.py - File: batch_processor.py - File: batch_processor.py - Database save failed: [<class 'decimal.ConversionSyntax'>]
2025-06-09 16:42:49,701 - src.processing.batch_processor - ERROR - File: batch_processor.py - File: batch_processor.py - File: batch_processor.py - File: batch_processor.py - File: batch_processor.py - [ERROR] Failed to process AB31CFD1-C61A-4637-A9C0-71B7C676AAA8.xml: Failed to save invoice to database
2025-06-09 16:48:22,698 - src.processing.gemini_classifier - ERROR - File: gemini_classifier.py - File: gemini_classifier.py - File: gemini_classifier.py - File: gemini_classifier.py - File: gemini_classifier.py - Gemini API failed after 3 attempts: 400 API key not valid. Please pass a valid API key. [reason: "API_KEY_INVALID"
domain: "googleapis.com"
metadata {
  key: "service"
  value: "generativelanguage.googleapis.com"
}
, locale: "en-US"
message: "API key not valid. Please pass a valid API key."
]
2025-06-09 16:48:22,700 - src.processing.gemini_classifier - ERROR - File: gemini_classifier.py - File: gemini_classifier.py - File: gemini_classifier.py - File: gemini_classifier.py - File: gemini_classifier.py - Classification failed for sku_141a86f5_10161506_naranja: Gemini API failed after 3 attempts: 400 API key not valid. Please pass a valid API key. [reason: "API_KEY_INVALID"
domain: "googleapis.com"
metadata {
  key: "service"
  value: "generativelanguage.googleapis.com"
}
, locale: "en-US"
message: "API key not valid. Please pass a valid API key."
]
2025-06-09 16:48:26,923 - src.processing.gemini_classifier - ERROR - File: gemini_classifier.py - File: gemini_classifier.py - File: gemini_classifier.py - File: gemini_classifier.py - File: gemini_classifier.py - Gemini API failed after 3 attempts: 400 API key not valid. Please pass a valid API key. [reason: "API_KEY_INVALID"
domain: "googleapis.com"
metadata {
  key: "service"
  value: "generativelanguage.googleapis.com"
}
, locale: "en-US"
message: "API key not valid. Please pass a valid API key."
]
2025-06-09 16:48:26,931 - src.processing.gemini_classifier - ERROR - File: gemini_classifier.py - File: gemini_classifier.py - File: gemini_classifier.py - File: gemini_classifier.py - File: gemini_classifier.py - Classification failed for sku_9a57e1c2_50304100_limon_sin_semilla: Gemini API failed after 3 attempts: 400 API key not valid. Please pass a valid API key. [reason: "API_KEY_INVALID"
domain: "googleapis.com"
metadata {
  key: "service"
  value: "generativelanguage.googleapis.com"
}
, locale: "en-US"
message: "API key not valid. Please pass a valid API key."
]
2025-06-09 16:48:30,568 - src.processing.gemini_classifier - ERROR - File: gemini_classifier.py - File: gemini_classifier.py - File: gemini_classifier.py - File: gemini_classifier.py - File: gemini_classifier.py - Gemini API failed after 3 attempts: 400 API key not valid. Please pass a valid API key. [reason: "API_KEY_INVALID"
domain: "googleapis.com"
metadata {
  key: "service"
  value: "generativelanguage.googleapis.com"
}
, locale: "en-US"
message: "API key not valid. Please pass a valid API key."
]
2025-06-09 16:48:30,575 - src.processing.gemini_classifier - ERROR - File: gemini_classifier.py - File: gemini_classifier.py - File: gemini_classifier.py - File: gemini_classifier.py - File: gemini_classifier.py - Classification failed for sku_64cd09d0_50202302_hielo_bolsa_de_hielo_5kg: Gemini API failed after 3 attempts: 400 API key not valid. Please pass a valid API key. [reason: "API_KEY_INVALID"
domain: "googleapis.com"
metadata {
  key: "service"
  value: "generativelanguage.googleapis.com"
}
, locale: "en-US"
message: "API key not valid. Please pass a valid API key."
]
2025-06-09 17:03:26,514 - src.processing.gemini_classifier - ERROR - File: gemini_classifier.py - File: gemini_classifier.py - File: gemini_classifier.py - File: gemini_classifier.py - File: gemini_classifier.py - Gemini API failed after 3 attempts: 400 API key not valid. Please pass a valid API key. [reason: "API_KEY_INVALID"
domain: "googleapis.com"
metadata {
  key: "service"
  value: "generativelanguage.googleapis.com"
}
, locale: "en-US"
message: "API key not valid. Please pass a valid API key."
]
2025-06-09 17:03:26,519 - src.processing.gemini_classifier - ERROR - File: gemini_classifier.py - File: gemini_classifier.py - File: gemini_classifier.py - File: gemini_classifier.py - File: gemini_classifier.py - Classification failed for sku_141a86f5_10161506_naranja: Gemini API failed after 3 attempts: 400 API key not valid. Please pass a valid API key. [reason: "API_KEY_INVALID"
domain: "googleapis.com"
metadata {
  key: "service"
  value: "generativelanguage.googleapis.com"
}
, locale: "en-US"
message: "API key not valid. Please pass a valid API key."
]
2025-06-09 17:03:30,034 - src.processing.gemini_classifier - ERROR - File: gemini_classifier.py - File: gemini_classifier.py - File: gemini_classifier.py - File: gemini_classifier.py - File: gemini_classifier.py - Gemini API failed after 3 attempts: 400 API key not valid. Please pass a valid API key. [reason: "API_KEY_INVALID"
domain: "googleapis.com"
metadata {
  key: "service"
  value: "generativelanguage.googleapis.com"
}
, locale: "en-US"
message: "API key not valid. Please pass a valid API key."
]
2025-06-09 17:03:30,040 - src.processing.gemini_classifier - ERROR - File: gemini_classifier.py - File: gemini_classifier.py - File: gemini_classifier.py - File: gemini_classifier.py - File: gemini_classifier.py - Classification failed for sku_9a57e1c2_50304100_limon_sin_semilla: Gemini API failed after 3 attempts: 400 API key not valid. Please pass a valid API key. [reason: "API_KEY_INVALID"
domain: "googleapis.com"
metadata {
  key: "service"
  value: "generativelanguage.googleapis.com"
}
, locale: "en-US"
message: "API key not valid. Please pass a valid API key."
]
2025-06-09 17:03:33,548 - src.processing.gemini_classifier - ERROR - File: gemini_classifier.py - File: gemini_classifier.py - File: gemini_classifier.py - File: gemini_classifier.py - File: gemini_classifier.py - Gemini API failed after 3 attempts: 400 API key not valid. Please pass a valid API key. [reason: "API_KEY_INVALID"
domain: "googleapis.com"
metadata {
  key: "service"
  value: "generativelanguage.googleapis.com"
}
, locale: "en-US"
message: "API key not valid. Please pass a valid API key."
]
2025-06-09 17:03:33,561 - src.processing.gemini_classifier - ERROR - File: gemini_classifier.py - File: gemini_classifier.py - File: gemini_classifier.py - File: gemini_classifier.py - File: gemini_classifier.py - Classification failed for sku_64cd09d0_50202302_hielo_bolsa_de_hielo_5kg: Gemini API failed after 3 attempts: 400 API key not valid. Please pass a valid API key. [reason: "API_KEY_INVALID"
domain: "googleapis.com"
metadata {
  key: "service"
  value: "generativelanguage.googleapis.com"
}
, locale: "en-US"
message: "API key not valid. Please pass a valid API key."
]
2025-06-09 17:03:37,090 - src.processing.gemini_classifier - ERROR - File: gemini_classifier.py - File: gemini_classifier.py - File: gemini_classifier.py - File: gemini_classifier.py - File: gemini_classifier.py - Gemini API failed after 3 attempts: 400 API key not valid. Please pass a valid API key. [reason: "API_KEY_INVALID"
domain: "googleapis.com"
metadata {
  key: "service"
  value: "generativelanguage.googleapis.com"
}
, locale: "en-US"
message: "API key not valid. Please pass a valid API key."
]
2025-06-09 17:03:37,093 - src.processing.gemini_classifier - ERROR - File: gemini_classifier.py - File: gemini_classifier.py - File: gemini_classifier.py - File: gemini_classifier.py - File: gemini_classifier.py - Classification failed for sku_6a2cfbaf_50131612_huevo_cartera_con_30pz: Gemini API failed after 3 attempts: 400 API key not valid. Please pass a valid API key. [reason: "API_KEY_INVALID"
domain: "googleapis.com"
metadata {
  key: "service"
  value: "generativelanguage.googleapis.com"
}
, locale: "en-US"
message: "API key not valid. Please pass a valid API key."
]
2025-06-09 17:09:23,095 - src.processing.gemini_classifier - ERROR - File: gemini_classifier.py - File: gemini_classifier.py - File: gemini_classifier.py - File: gemini_classifier.py - File: gemini_classifier.py - Gemini API failed after 3 attempts: 400 API key not valid. Please pass a valid API key. [reason: "API_KEY_INVALID"
domain: "googleapis.com"
metadata {
  key: "service"
  value: "generativelanguage.googleapis.com"
}
, locale: "en-US"
message: "API key not valid. Please pass a valid API key."
]
2025-06-09 17:09:23,100 - src.processing.gemini_classifier - ERROR - File: gemini_classifier.py - File: gemini_classifier.py - File: gemini_classifier.py - File: gemini_classifier.py - File: gemini_classifier.py - Classification failed for sku_141a86f5_10161506_naranja: Gemini API failed after 3 attempts: 400 API key not valid. Please pass a valid API key. [reason: "API_KEY_INVALID"
domain: "googleapis.com"
metadata {
  key: "service"
  value: "generativelanguage.googleapis.com"
}
, locale: "en-US"
message: "API key not valid. Please pass a valid API key."
]
2025-06-09 17:09:26,606 - src.processing.gemini_classifier - ERROR - File: gemini_classifier.py - File: gemini_classifier.py - File: gemini_classifier.py - File: gemini_classifier.py - File: gemini_classifier.py - Gemini API failed after 3 attempts: 400 API key not valid. Please pass a valid API key. [reason: "API_KEY_INVALID"
domain: "googleapis.com"
metadata {
  key: "service"
  value: "generativelanguage.googleapis.com"
}
, locale: "en-US"
message: "API key not valid. Please pass a valid API key."
]
2025-06-09 17:09:26,609 - src.processing.gemini_classifier - ERROR - File: gemini_classifier.py - File: gemini_classifier.py - File: gemini_classifier.py - File: gemini_classifier.py - File: gemini_classifier.py - Classification failed for sku_9a57e1c2_50304100_limon_sin_semilla: Gemini API failed after 3 attempts: 400 API key not valid. Please pass a valid API key. [reason: "API_KEY_INVALID"
domain: "googleapis.com"
metadata {
  key: "service"
  value: "generativelanguage.googleapis.com"
}
, locale: "en-US"
message: "API key not valid. Please pass a valid API key."
]
2025-06-09 17:09:30,090 - src.processing.gemini_classifier - ERROR - File: gemini_classifier.py - File: gemini_classifier.py - File: gemini_classifier.py - File: gemini_classifier.py - File: gemini_classifier.py - Gemini API failed after 3 attempts: 400 API key not valid. Please pass a valid API key. [reason: "API_KEY_INVALID"
domain: "googleapis.com"
metadata {
  key: "service"
  value: "generativelanguage.googleapis.com"
}
, locale: "en-US"
message: "API key not valid. Please pass a valid API key."
]
2025-06-09 17:09:30,091 - src.processing.gemini_classifier - ERROR - File: gemini_classifier.py - File: gemini_classifier.py - File: gemini_classifier.py - File: gemini_classifier.py - File: gemini_classifier.py - Classification failed for sku_64cd09d0_50202302_hielo_bolsa_de_hielo_5kg: Gemini API failed after 3 attempts: 400 API key not valid. Please pass a valid API key. [reason: "API_KEY_INVALID"
domain: "googleapis.com"
metadata {
  key: "service"
  value: "generativelanguage.googleapis.com"
}
, locale: "en-US"
message: "API key not valid. Please pass a valid API key."
]
2025-06-09 17:09:33,573 - src.processing.gemini_classifier - ERROR - File: gemini_classifier.py - File: gemini_classifier.py - File: gemini_classifier.py - File: gemini_classifier.py - File: gemini_classifier.py - Gemini API failed after 3 attempts: 400 API key not valid. Please pass a valid API key. [reason: "API_KEY_INVALID"
domain: "googleapis.com"
metadata {
  key: "service"
  value: "generativelanguage.googleapis.com"
}
, locale: "en-US"
message: "API key not valid. Please pass a valid API key."
]
2025-06-09 17:09:33,578 - src.processing.gemini_classifier - ERROR - File: gemini_classifier.py - File: gemini_classifier.py - File: gemini_classifier.py - File: gemini_classifier.py - File: gemini_classifier.py - Classification failed for sku_6a2cfbaf_50131612_huevo_cartera_con_30pz: Gemini API failed after 3 attempts: 400 API key not valid. Please pass a valid API key. [reason: "API_KEY_INVALID"
domain: "googleapis.com"
metadata {
  key: "service"
  value: "generativelanguage.googleapis.com"
}
, locale: "en-US"
message: "API key not valid. Please pass a valid API key."
]
2025-06-09 17:11:28,610 - src.processing.gemini_classifier - ERROR - File: gemini_classifier.py - File: gemini_classifier.py - File: gemini_classifier.py - File: gemini_classifier.py - File: gemini_classifier.py - Gemini API failed after 3 attempts: 400 API key not valid. Please pass a valid API key. [reason: "API_KEY_INVALID"
domain: "googleapis.com"
metadata {
  key: "service"
  value: "generativelanguage.googleapis.com"
}
, locale: "en-US"
message: "API key not valid. Please pass a valid API key."
]
2025-06-09 17:11:28,617 - src.processing.gemini_classifier - ERROR - File: gemini_classifier.py - File: gemini_classifier.py - File: gemini_classifier.py - File: gemini_classifier.py - File: gemini_classifier.py - Classification failed for sku_141a86f5_10161506_naranja: Gemini API failed after 3 attempts: 400 API key not valid. Please pass a valid API key. [reason: "API_KEY_INVALID"
domain: "googleapis.com"
metadata {
  key: "service"
  value: "generativelanguage.googleapis.com"
}
, locale: "en-US"
message: "API key not valid. Please pass a valid API key."
]
2025-06-09 17:34:36,839 - src.processing.gemini_classifier - ERROR - File: gemini_classifier.py - File: gemini_classifier.py - File: gemini_classifier.py - File: gemini_classifier.py - File: gemini_classifier.py - Gemini API failed after 3 attempts: 400 API key not valid. Please pass a valid API key. [reason: "API_KEY_INVALID"
domain: "googleapis.com"
metadata {
  key: "service"
  value: "generativelanguage.googleapis.com"
}
, locale: "en-US"
message: "API key not valid. Please pass a valid API key."
]
2025-06-09 17:34:36,840 - src.processing.gemini_classifier - ERROR - File: gemini_classifier.py - File: gemini_classifier.py - File: gemini_classifier.py - File: gemini_classifier.py - File: gemini_classifier.py - Classification failed for sku_141a86f5_10161506_naranja: Gemini API failed after 3 attempts: 400 API key not valid. Please pass a valid API key. [reason: "API_KEY_INVALID"
domain: "googleapis.com"
metadata {
  key: "service"
  value: "generativelanguage.googleapis.com"
}
, locale: "en-US"
message: "API key not valid. Please pass a valid API key."
]
2025-06-09 17:40:09,764 - src.processing.gemini_classifier - ERROR - File: gemini_classifier.py - File: gemini_classifier.py - File: gemini_classifier.py - File: gemini_classifier.py - File: gemini_classifier.py - Gemini API failed after 3 attempts: 400 API key not valid. Please pass a valid API key. [reason: "API_KEY_INVALID"
domain: "googleapis.com"
metadata {
  key: "service"
  value: "generativelanguage.googleapis.com"
}
, locale: "en-US"
message: "API key not valid. Please pass a valid API key."
]
2025-06-09 17:40:09,765 - src.processing.gemini_classifier - ERROR - File: gemini_classifier.py - File: gemini_classifier.py - File: gemini_classifier.py - File: gemini_classifier.py - File: gemini_classifier.py - Classification failed for sku_141a86f5_10161506_naranja: Gemini API failed after 3 attempts: 400 API key not valid. Please pass a valid API key. [reason: "API_KEY_INVALID"
domain: "googleapis.com"
metadata {
  key: "service"
  value: "generativelanguage.googleapis.com"
}
, locale: "en-US"
message: "API key not valid. Please pass a valid API key."
]
2025-06-09 17:40:13,235 - src.processing.gemini_classifier - ERROR - File: gemini_classifier.py - File: gemini_classifier.py - File: gemini_classifier.py - File: gemini_classifier.py - File: gemini_classifier.py - Gemini API failed after 3 attempts: 400 API key not valid. Please pass a valid API key. [reason: "API_KEY_INVALID"
domain: "googleapis.com"
metadata {
  key: "service"
  value: "generativelanguage.googleapis.com"
}
, locale: "en-US"
message: "API key not valid. Please pass a valid API key."
]
2025-06-09 17:40:13,240 - src.processing.gemini_classifier - ERROR - File: gemini_classifier.py - File: gemini_classifier.py - File: gemini_classifier.py - File: gemini_classifier.py - File: gemini_classifier.py - Classification failed for sku_9a57e1c2_50304100_limon_sin_semilla: Gemini API failed after 3 attempts: 400 API key not valid. Please pass a valid API key. [reason: "API_KEY_INVALID"
domain: "googleapis.com"
metadata {
  key: "service"
  value: "generativelanguage.googleapis.com"
}
, locale: "en-US"
message: "API key not valid. Please pass a valid API key."
]
2025-06-09 17:40:16,716 - src.processing.gemini_classifier - ERROR - File: gemini_classifier.py - File: gemini_classifier.py - File: gemini_classifier.py - File: gemini_classifier.py - File: gemini_classifier.py - Gemini API failed after 3 attempts: 400 API key not valid. Please pass a valid API key. [reason: "API_KEY_INVALID"
domain: "googleapis.com"
metadata {
  key: "service"
  value: "generativelanguage.googleapis.com"
}
, locale: "en-US"
message: "API key not valid. Please pass a valid API key."
]
2025-06-09 17:40:16,720 - src.processing.gemini_classifier - ERROR - File: gemini_classifier.py - File: gemini_classifier.py - File: gemini_classifier.py - File: gemini_classifier.py - File: gemini_classifier.py - Classification failed for sku_64cd09d0_50202302_hielo_bolsa_de_hielo_5kg: Gemini API failed after 3 attempts: 400 API key not valid. Please pass a valid API key. [reason: "API_KEY_INVALID"
domain: "googleapis.com"
metadata {
  key: "service"
  value: "generativelanguage.googleapis.com"
}
, locale: "en-US"
message: "API key not valid. Please pass a valid API key."
]
2025-06-09 17:40:20,193 - src.processing.gemini_classifier - ERROR - File: gemini_classifier.py - File: gemini_classifier.py - File: gemini_classifier.py - File: gemini_classifier.py - File: gemini_classifier.py - Gemini API failed after 3 attempts: 400 API key not valid. Please pass a valid API key. [reason: "API_KEY_INVALID"
domain: "googleapis.com"
metadata {
  key: "service"
  value: "generativelanguage.googleapis.com"
}
, locale: "en-US"
message: "API key not valid. Please pass a valid API key."
]
2025-06-09 17:40:20,197 - src.processing.gemini_classifier - ERROR - File: gemini_classifier.py - File: gemini_classifier.py - File: gemini_classifier.py - File: gemini_classifier.py - File: gemini_classifier.py - Classification failed for sku_6a2cfbaf_50131612_huevo_cartera_con_30pz: Gemini API failed after 3 attempts: 400 API key not valid. Please pass a valid API key. [reason: "API_KEY_INVALID"
domain: "googleapis.com"
metadata {
  key: "service"
  value: "generativelanguage.googleapis.com"
}
, locale: "en-US"
message: "API key not valid. Please pass a valid API key."
]
2025-06-09 17:40:23,690 - src.processing.gemini_classifier - ERROR - File: gemini_classifier.py - File: gemini_classifier.py - File: gemini_classifier.py - File: gemini_classifier.py - File: gemini_classifier.py - Gemini API failed after 3 attempts: 400 API key not valid. Please pass a valid API key. [reason: "API_KEY_INVALID"
domain: "googleapis.com"
metadata {
  key: "service"
  value: "generativelanguage.googleapis.com"
}
, locale: "en-US"
message: "API key not valid. Please pass a valid API key."
]
2025-06-09 17:40:23,692 - src.processing.gemini_classifier - ERROR - File: gemini_classifier.py - File: gemini_classifier.py - File: gemini_classifier.py - File: gemini_classifier.py - File: gemini_classifier.py - Classification failed for sku_3823c19d_50405300_cebolla_blanca: Gemini API failed after 3 attempts: 400 API key not valid. Please pass a valid API key. [reason: "API_KEY_INVALID"
domain: "googleapis.com"
metadata {
  key: "service"
  value: "generativelanguage.googleapis.com"
}
, locale: "en-US"
message: "API key not valid. Please pass a valid API key."
]
2025-06-09 17:40:27,214 - src.processing.gemini_classifier - ERROR - File: gemini_classifier.py - File: gemini_classifier.py - File: gemini_classifier.py - File: gemini_classifier.py - File: gemini_classifier.py - Gemini API failed after 3 attempts: 400 API key not valid. Please pass a valid API key. [reason: "API_KEY_INVALID"
domain: "googleapis.com"
metadata {
  key: "service"
  value: "generativelanguage.googleapis.com"
}
, locale: "en-US"
message: "API key not valid. Please pass a valid API key."
]
2025-06-09 17:40:27,217 - src.processing.gemini_classifier - ERROR - File: gemini_classifier.py - File: gemini_classifier.py - File: gemini_classifier.py - File: gemini_classifier.py - File: gemini_classifier.py - Classification failed for sku_65d00f8a_50404101_albahaca: Gemini API failed after 3 attempts: 400 API key not valid. Please pass a valid API key. [reason: "API_KEY_INVALID"
domain: "googleapis.com"
metadata {
  key: "service"
  value: "generativelanguage.googleapis.com"
}
, locale: "en-US"
message: "API key not valid. Please pass a valid API key."
]
2025-06-09 17:40:30,701 - src.processing.gemini_classifier - ERROR - File: gemini_classifier.py - File: gemini_classifier.py - File: gemini_classifier.py - File: gemini_classifier.py - File: gemini_classifier.py - Gemini API failed after 3 attempts: 400 API key not valid. Please pass a valid API key. [reason: "API_KEY_INVALID"
domain: "googleapis.com"
metadata {
  key: "service"
  value: "generativelanguage.googleapis.com"
}
, locale: "en-US"
message: "API key not valid. Please pass a valid API key."
]
2025-06-09 17:40:30,704 - src.processing.gemini_classifier - ERROR - File: gemini_classifier.py - File: gemini_classifier.py - File: gemini_classifier.py - File: gemini_classifier.py - File: gemini_classifier.py - Classification failed for sku_44f0bbec_50403900_calabaza_negra: Gemini API failed after 3 attempts: 400 API key not valid. Please pass a valid API key. [reason: "API_KEY_INVALID"
domain: "googleapis.com"
metadata {
  key: "service"
  value: "generativelanguage.googleapis.com"
}
, locale: "en-US"
message: "API key not valid. Please pass a valid API key."
]
2025-06-09 17:40:34,181 - src.processing.gemini_classifier - ERROR - File: gemini_classifier.py - File: gemini_classifier.py - File: gemini_classifier.py - File: gemini_classifier.py - File: gemini_classifier.py - Gemini API failed after 3 attempts: 400 API key not valid. Please pass a valid API key. [reason: "API_KEY_INVALID"
domain: "googleapis.com"
metadata {
  key: "service"
  value: "generativelanguage.googleapis.com"
}
, locale: "en-US"
message: "API key not valid. Please pass a valid API key."
]
2025-06-09 17:40:34,186 - src.processing.gemini_classifier - ERROR - File: gemini_classifier.py - File: gemini_classifier.py - File: gemini_classifier.py - File: gemini_classifier.py - File: gemini_classifier.py - Classification failed for sku_9694c503_50403500_berenjena: Gemini API failed after 3 attempts: 400 API key not valid. Please pass a valid API key. [reason: "API_KEY_INVALID"
domain: "googleapis.com"
metadata {
  key: "service"
  value: "generativelanguage.googleapis.com"
}
, locale: "en-US"
message: "API key not valid. Please pass a valid API key."
]
2025-06-09 17:40:37,644 - src.processing.gemini_classifier - ERROR - File: gemini_classifier.py - File: gemini_classifier.py - File: gemini_classifier.py - File: gemini_classifier.py - File: gemini_classifier.py - Gemini API failed after 3 attempts: 400 API key not valid. Please pass a valid API key. [reason: "API_KEY_INVALID"
domain: "googleapis.com"
metadata {
  key: "service"
  value: "generativelanguage.googleapis.com"
}
, locale: "en-US"
message: "API key not valid. Please pass a valid API key."
]
2025-06-09 17:40:37,646 - src.processing.gemini_classifier - ERROR - File: gemini_classifier.py - File: gemini_classifier.py - File: gemini_classifier.py - File: gemini_classifier.py - File: gemini_classifier.py - Classification failed for sku_09573e71_50417006_arugula: Gemini API failed after 3 attempts: 400 API key not valid. Please pass a valid API key. [reason: "API_KEY_INVALID"
domain: "googleapis.com"
metadata {
  key: "service"
  value: "generativelanguage.googleapis.com"
}
, locale: "en-US"
message: "API key not valid. Please pass a valid API key."
]
2025-06-09 17:40:41,119 - src.processing.gemini_classifier - ERROR - File: gemini_classifier.py - File: gemini_classifier.py - File: gemini_classifier.py - File: gemini_classifier.py - File: gemini_classifier.py - Gemini API failed after 3 attempts: 400 API key not valid. Please pass a valid API key. [reason: "API_KEY_INVALID"
domain: "googleapis.com"
metadata {
  key: "service"
  value: "generativelanguage.googleapis.com"
}
, locale: "en-US"
message: "API key not valid. Please pass a valid API key."
]
2025-06-09 17:40:41,121 - src.processing.gemini_classifier - ERROR - File: gemini_classifier.py - File: gemini_classifier.py - File: gemini_classifier.py - File: gemini_classifier.py - File: gemini_classifier.py - Classification failed for sku_6a416cf3_50131800_queso_fresco: Gemini API failed after 3 attempts: 400 API key not valid. Please pass a valid API key. [reason: "API_KEY_INVALID"
domain: "googleapis.com"
metadata {
  key: "service"
  value: "generativelanguage.googleapis.com"
}
, locale: "en-US"
message: "API key not valid. Please pass a valid API key."
]
2025-06-09 17:40:44,617 - src.processing.gemini_classifier - ERROR - File: gemini_classifier.py - File: gemini_classifier.py - File: gemini_classifier.py - File: gemini_classifier.py - File: gemini_classifier.py - Gemini API failed after 3 attempts: 400 API key not valid. Please pass a valid API key. [reason: "API_KEY_INVALID"
domain: "googleapis.com"
metadata {
  key: "service"
  value: "generativelanguage.googleapis.com"
}
, locale: "en-US"
message: "API key not valid. Please pass a valid API key."
]
2025-06-09 17:40:44,620 - src.processing.gemini_classifier - ERROR - File: gemini_classifier.py - File: gemini_classifier.py - File: gemini_classifier.py - File: gemini_classifier.py - File: gemini_classifier.py - Classification failed for sku_2df84722_50221001_arroz_verde_valle_500gr: Gemini API failed after 3 attempts: 400 API key not valid. Please pass a valid API key. [reason: "API_KEY_INVALID"
domain: "googleapis.com"
metadata {
  key: "service"
  value: "generativelanguage.googleapis.com"
}
, locale: "en-US"
message: "API key not valid. Please pass a valid API key."
]
2025-06-09 17:40:48,134 - src.processing.gemini_classifier - ERROR - File: gemini_classifier.py - File: gemini_classifier.py - File: gemini_classifier.py - File: gemini_classifier.py - File: gemini_classifier.py - Gemini API failed after 3 attempts: 400 API key not valid. Please pass a valid API key. [reason: "API_KEY_INVALID"
domain: "googleapis.com"
metadata {
  key: "service"
  value: "generativelanguage.googleapis.com"
}
, locale: "en-US"
message: "API key not valid. Please pass a valid API key."
]
2025-06-09 17:40:48,186 - src.processing.gemini_classifier - ERROR - File: gemini_classifier.py - File: gemini_classifier.py - File: gemini_classifier.py - File: gemini_classifier.py - File: gemini_classifier.py - Classification failed for sku_c0496069_50406500_tomate_salades: Gemini API failed after 3 attempts: 400 API key not valid. Please pass a valid API key. [reason: "API_KEY_INVALID"
domain: "googleapis.com"
metadata {
  key: "service"
  value: "generativelanguage.googleapis.com"
}
, locale: "en-US"
message: "API key not valid. Please pass a valid API key."
]
2025-06-09 17:40:51,833 - src.processing.gemini_classifier - ERROR - File: gemini_classifier.py - File: gemini_classifier.py - File: gemini_classifier.py - File: gemini_classifier.py - File: gemini_classifier.py - Gemini API failed after 3 attempts: 400 API key not valid. Please pass a valid API key. [reason: "API_KEY_INVALID"
domain: "googleapis.com"
metadata {
  key: "service"
  value: "generativelanguage.googleapis.com"
}
, locale: "en-US"
message: "API key not valid. Please pass a valid API key."
]
2025-06-09 17:40:51,835 - src.processing.gemini_classifier - ERROR - File: gemini_classifier.py - File: gemini_classifier.py - File: gemini_classifier.py - File: gemini_classifier.py - File: gemini_classifier.py - Classification failed for sku_11cd495e_50401700_aguacate: Gemini API failed after 3 attempts: 400 API key not valid. Please pass a valid API key. [reason: "API_KEY_INVALID"
domain: "googleapis.com"
metadata {
  key: "service"
  value: "generativelanguage.googleapis.com"
}
, locale: "en-US"
message: "API key not valid. Please pass a valid API key."
]
2025-06-09 17:40:55,350 - src.processing.gemini_classifier - ERROR - File: gemini_classifier.py - File: gemini_classifier.py - File: gemini_classifier.py - File: gemini_classifier.py - File: gemini_classifier.py - Gemini API failed after 3 attempts: 400 API key not valid. Please pass a valid API key. [reason: "API_KEY_INVALID"
domain: "googleapis.com"
metadata {
  key: "service"
  value: "generativelanguage.googleapis.com"
}
, locale: "en-US"
message: "API key not valid. Please pass a valid API key."
]
2025-06-09 17:40:55,354 - src.processing.gemini_classifier - ERROR - File: gemini_classifier.py - File: gemini_classifier.py - File: gemini_classifier.py - File: gemini_classifier.py - File: gemini_classifier.py - Classification failed for sku_ac43b4be_27112003_rastrillo: Gemini API failed after 3 attempts: 400 API key not valid. Please pass a valid API key. [reason: "API_KEY_INVALID"
domain: "googleapis.com"
metadata {
  key: "service"
  value: "generativelanguage.googleapis.com"
}
, locale: "en-US"
message: "API key not valid. Please pass a valid API key."
]
2025-06-09 17:40:58,878 - src.processing.gemini_classifier - ERROR - File: gemini_classifier.py - File: gemini_classifier.py - File: gemini_classifier.py - File: gemini_classifier.py - File: gemini_classifier.py - Gemini API failed after 3 attempts: 400 API key not valid. Please pass a valid API key. [reason: "API_KEY_INVALID"
domain: "googleapis.com"
metadata {
  key: "service"
  value: "generativelanguage.googleapis.com"
}
, locale: "en-US"
message: "API key not valid. Please pass a valid API key."
]
2025-06-09 17:40:58,878 - src.processing.gemini_classifier - ERROR - File: gemini_classifier.py - File: gemini_classifier.py - File: gemini_classifier.py - File: gemini_classifier.py - File: gemini_classifier.py - Classification failed for sku_6a2cfbaf_50131612_huevo_cartera_con_30pz: Gemini API failed after 3 attempts: 400 API key not valid. Please pass a valid API key. [reason: "API_KEY_INVALID"
domain: "googleapis.com"
metadata {
  key: "service"
  value: "generativelanguage.googleapis.com"
}
, locale: "en-US"
message: "API key not valid. Please pass a valid API key."
]
2025-06-09 17:41:02,408 - src.processing.gemini_classifier - ERROR - File: gemini_classifier.py - File: gemini_classifier.py - File: gemini_classifier.py - File: gemini_classifier.py - File: gemini_classifier.py - Gemini API failed after 3 attempts: 400 API key not valid. Please pass a valid API key. [reason: "API_KEY_INVALID"
domain: "googleapis.com"
metadata {
  key: "service"
  value: "generativelanguage.googleapis.com"
}
, locale: "en-US"
message: "API key not valid. Please pass a valid API key."
]
2025-06-09 17:41:02,410 - src.processing.gemini_classifier - ERROR - File: gemini_classifier.py - File: gemini_classifier.py - File: gemini_classifier.py - File: gemini_classifier.py - File: gemini_classifier.py - Classification failed for sku_d71b9f5d_52152200_fibra: Gemini API failed after 3 attempts: 400 API key not valid. Please pass a valid API key. [reason: "API_KEY_INVALID"
domain: "googleapis.com"
metadata {
  key: "service"
  value: "generativelanguage.googleapis.com"
}
, locale: "en-US"
message: "API key not valid. Please pass a valid API key."
]
2025-06-09 17:41:02,455 - src.data.database - ERROR - File: database.py - File: database.py - File: database.py - File: database.py - File: database.py - Database session error: (sqlite3.IntegrityError) UNIQUE constraint failed: invoices.uuid
[SQL: INSERT INTO invoices (uuid, series, folio, invoice_type, version, issue_date, certification_date, created_at, updated_at, issuer_rfc, issuer_name, issuer_fiscal_regime, issuer_use_cfdi, issuer_residence, issuer_tax_id, receiver_rfc, receiver_name, receiver_fiscal_address, receiver_residence, receiver_tax_id, receiver_use_cfdi, payment_method, payment_method_desc, payment_terms, payment_conditions, currency, exchange_rate, subtotal, total_discount, total_transferred_taxes, total_withheld_taxes, total_amount, digital_stamp, certificate_number, certificate, sat_seal, sat_certificate, fiscal_folio, stamp_datetime, expedition_place, export_operation, confirmation, source_filename, xml_file_size, confidence_score, processing_time, processing_status) VALUES (?, ?, ?, ?, ?, ?, ?, ?, ?, ?, ?, ?, ?, ?, ?, ?, ?, ?, ?, ?, ?, ?, ?, ?, ?, ?, ?, ?, ?, ?, ?, ?, ?, ?, ?, ?, ?, ?, ?, ?, ?, ?, ?, ?, ?, ?, ?)]
[parameters: ('AB31CFD1-C61A-4637-A9C0-71B7C676AAA8', None, '50389', 'I', '4.0', '2025-06-10 00:41:02.419626', None, '2025-06-10 00:41:02.438807', '2025-06-10 00:41:02.438807', 'PIVV******RR4', 'VANESSA IVON PIÑUELAS VERDUGO', '612', None, None, None, 'YUGY******FK4', 'YASSER YUSSIF GONZALEZ', '23300', None, None, None, '99', None, 'PPD', None, 'MXN', 1.0, 1109.9, 0.0, 6.9, 0.0, 1116.8, 'aQfQopzRPLxulkiqjktVYxiduTpNrSwDB4dZP7PvCBUrQRR/5XUvRHyKPVX61EQKhLEtbj5g2e14t+RfCi5th3rxKRsSQZatC8ftc9fPXtn6MoSywmSTLDz8MnUjHtvHfEd2AHn3UshIjneQOCBbR ... (46 characters truncated) ... rrDojl3CGXeigZqDuSgBIdy6YMzLYlsUN1AomwMjwQI3a61pF3RBsIfZwnmvRHsUa0EOLHc+F5GQJHpWDynRz3zuGjxjQal24uz2XiSUXLqjGYLo3CrxBe+XbGJ8/wXE5Z5POE3AJ0QuszTCyyw==', '00001000000705018977', None, 'gJTwCIW7z1Ill/xpC6f2EBZYisQKGq7LKRPZyZ7Oq8fC074zWIb8qCpOIKEUNeEWBE1V+7PUvxSA44RrhqKq6+k1RZojgIrm8xqPO4uiItCDVFwlPK0Vyi6wUJNfrgnx2yCLped62LdAxyQrL+Gc4 ... (46 characters truncated) ... yPIGMDuKo3U+wIpQ2QhnK4R1ZFm/foyowBdQ8XzMXH2tw/9L1PSn1rUIZC0RpV7kOfmS5WQXsIOpkA6VQnRH7cNVBjC3XgOU1wyxKYRq9QBpE2aCA1wqm4qvDaofIEgXZRUjWTGBaz/JUfWpjoQ==', None, 'AB31CFD1-C61A-4637-A9C0-71B7C676AAA8', '2025-06-10 00:41:02.421845', None, None, None, 'AB31CFD1-C61A-4637-A9C0-71B7C676AAA8.xml', 10794, None, None, 'processed')]
(Background on this error at: https://sqlalche.me/e/20/gkpj)
2025-06-09 17:41:02,460 - src.processing.batch_processor - ERROR - File: batch_processor.py - File: batch_processor.py - File: batch_processor.py - File: batch_processor.py - File: batch_processor.py - Database save failed: (sqlite3.IntegrityError) UNIQUE constraint failed: invoices.uuid
[SQL: INSERT INTO invoices (uuid, series, folio, invoice_type, version, issue_date, certification_date, created_at, updated_at, issuer_rfc, issuer_name, issuer_fiscal_regime, issuer_use_cfdi, issuer_residence, issuer_tax_id, receiver_rfc, receiver_name, receiver_fiscal_address, receiver_residence, receiver_tax_id, receiver_use_cfdi, payment_method, payment_method_desc, payment_terms, payment_conditions, currency, exchange_rate, subtotal, total_discount, total_transferred_taxes, total_withheld_taxes, total_amount, digital_stamp, certificate_number, certificate, sat_seal, sat_certificate, fiscal_folio, stamp_datetime, expedition_place, export_operation, confirmation, source_filename, xml_file_size, confidence_score, processing_time, processing_status) VALUES (?, ?, ?, ?, ?, ?, ?, ?, ?, ?, ?, ?, ?, ?, ?, ?, ?, ?, ?, ?, ?, ?, ?, ?, ?, ?, ?, ?, ?, ?, ?, ?, ?, ?, ?, ?, ?, ?, ?, ?, ?, ?, ?, ?, ?, ?, ?)]
[parameters: ('AB31CFD1-C61A-4637-A9C0-71B7C676AAA8', None, '50389', 'I', '4.0', '2025-06-10 00:41:02.419626', None, '2025-06-10 00:41:02.438807', '2025-06-10 00:41:02.438807', 'PIVV******RR4', 'VANESSA IVON PIÑUELAS VERDUGO', '612', None, None, None, 'YUGY******FK4', 'YASSER YUSSIF GONZALEZ', '23300', None, None, None, '99', None, 'PPD', None, 'MXN', 1.0, 1109.9, 0.0, 6.9, 0.0, 1116.8, 'aQfQopzRPLxulkiqjktVYxiduTpNrSwDB4dZP7PvCBUrQRR/5XUvRHyKPVX61EQKhLEtbj5g2e14t+RfCi5th3rxKRsSQZatC8ftc9fPXtn6MoSywmSTLDz8MnUjHtvHfEd2AHn3UshIjneQOCBbR ... (46 characters truncated) ... rrDojl3CGXeigZqDuSgBIdy6YMzLYlsUN1AomwMjwQI3a61pF3RBsIfZwnmvRHsUa0EOLHc+F5GQJHpWDynRz3zuGjxjQal24uz2XiSUXLqjGYLo3CrxBe+XbGJ8/wXE5Z5POE3AJ0QuszTCyyw==', '00001000000705018977', None, 'gJTwCIW7z1Ill/xpC6f2EBZYisQKGq7LKRPZyZ7Oq8fC074zWIb8qCpOIKEUNeEWBE1V+7PUvxSA44RrhqKq6+k1RZojgIrm8xqPO4uiItCDVFwlPK0Vyi6wUJNfrgnx2yCLped62LdAxyQrL+Gc4 ... (46 characters truncated) ... yPIGMDuKo3U+wIpQ2QhnK4R1ZFm/foyowBdQ8XzMXH2tw/9L1PSn1rUIZC0RpV7kOfmS5WQXsIOpkA6VQnRH7cNVBjC3XgOU1wyxKYRq9QBpE2aCA1wqm4qvDaofIEgXZRUjWTGBaz/JUfWpjoQ==', None, 'AB31CFD1-C61A-4637-A9C0-71B7C676AAA8', '2025-06-10 00:41:02.421845', None, None, None, 'AB31CFD1-C61A-4637-A9C0-71B7C676AAA8.xml', 10794, None, None, 'processed')]
(Background on this error at: https://sqlalche.me/e/20/gkpj)
2025-06-09 17:41:02,468 - src.processing.batch_processor - ERROR - File: batch_processor.py - File: batch_processor.py - File: batch_processor.py - File: batch_processor.py - File: batch_processor.py - [ERROR] Failed to process AB31CFD1-C61A-4637-A9C0-71B7C676AAA8.xml: Failed to save invoice to database
2025-06-09 17:42:09,167 - src.data.database - ERROR - File: database.py - File: database.py - File: database.py - File: database.py - File: database.py - Database session error: (sqlite3.IntegrityError) UNIQUE constraint failed: invoices.uuid
[SQL: INSERT INTO invoices (uuid, series, folio, invoice_type, version, issue_date, certification_date, created_at, updated_at, issuer_rfc, issuer_name, issuer_fiscal_regime, issuer_use_cfdi, issuer_residence, issuer_tax_id, receiver_rfc, receiver_name, receiver_fiscal_address, receiver_residence, receiver_tax_id, receiver_use_cfdi, payment_method, payment_method_desc, payment_terms, payment_conditions, currency, exchange_rate, subtotal, total_discount, total_transferred_taxes, total_withheld_taxes, total_amount, digital_stamp, certificate_number, certificate, sat_seal, sat_certificate, fiscal_folio, stamp_datetime, expedition_place, export_operation, confirmation, source_filename, xml_file_size, confidence_score, processing_time, processing_status) VALUES (?, ?, ?, ?, ?, ?, ?, ?, ?, ?, ?, ?, ?, ?, ?, ?, ?, ?, ?, ?, ?, ?, ?, ?, ?, ?, ?, ?, ?, ?, ?, ?, ?, ?, ?, ?, ?, ?, ?, ?, ?, ?, ?, ?, ?, ?, ?)]
[parameters: ('AB31CFD1-C61A-4637-A9C0-71B7C676AAA8', None, '50389', 'I', '4.0', '2025-06-10 00:42:09.105549', None, '2025-06-10 00:42:09.139907', '2025-06-10 00:42:09.139907', 'PIVV******RR4', 'VANESSA IVON PIÑUELAS VERDUGO', '612', None, None, None, 'YUGY******FK4', 'YASSER YUSSIF GONZALEZ', '23300', None, None, None, '99', None, 'PPD', None, 'MXN', 1.0, 1109.9, 0.0, 6.9, 0.0, 1116.8, 'aQfQopzRPLxulkiqjktVYxiduTpNrSwDB4dZP7PvCBUrQRR/5XUvRHyKPVX61EQKhLEtbj5g2e14t+RfCi5th3rxKRsSQZatC8ftc9fPXtn6MoSywmSTLDz8MnUjHtvHfEd2AHn3UshIjneQOCBbR ... (46 characters truncated) ... rrDojl3CGXeigZqDuSgBIdy6YMzLYlsUN1AomwMjwQI3a61pF3RBsIfZwnmvRHsUa0EOLHc+F5GQJHpWDynRz3zuGjxjQal24uz2XiSUXLqjGYLo3CrxBe+XbGJ8/wXE5Z5POE3AJ0QuszTCyyw==', '00001000000705018977', None, 'gJTwCIW7z1Ill/xpC6f2EBZYisQKGq7LKRPZyZ7Oq8fC074zWIb8qCpOIKEUNeEWBE1V+7PUvxSA44RrhqKq6+k1RZojgIrm8xqPO4uiItCDVFwlPK0Vyi6wUJNfrgnx2yCLped62LdAxyQrL+Gc4 ... (46 characters truncated) ... yPIGMDuKo3U+wIpQ2QhnK4R1ZFm/foyowBdQ8XzMXH2tw/9L1PSn1rUIZC0RpV7kOfmS5WQXsIOpkA6VQnRH7cNVBjC3XgOU1wyxKYRq9QBpE2aCA1wqm4qvDaofIEgXZRUjWTGBaz/JUfWpjoQ==', None, 'AB31CFD1-C61A-4637-A9C0-71B7C676AAA8', '2025-06-10 00:42:09.115910', None, None, None, 'AB31CFD1-C61A-4637-A9C0-71B7C676AAA8.xml', 10794, None, None, 'processed')]
(Background on this error at: https://sqlalche.me/e/20/gkpj)
2025-06-09 17:42:09,181 - src.processing.batch_processor - ERROR - File: batch_processor.py - File: batch_processor.py - File: batch_processor.py - File: batch_processor.py - File: batch_processor.py - Database save failed: (sqlite3.IntegrityError) UNIQUE constraint failed: invoices.uuid
[SQL: INSERT INTO invoices (uuid, series, folio, invoice_type, version, issue_date, certification_date, created_at, updated_at, issuer_rfc, issuer_name, issuer_fiscal_regime, issuer_use_cfdi, issuer_residence, issuer_tax_id, receiver_rfc, receiver_name, receiver_fiscal_address, receiver_residence, receiver_tax_id, receiver_use_cfdi, payment_method, payment_method_desc, payment_terms, payment_conditions, currency, exchange_rate, subtotal, total_discount, total_transferred_taxes, total_withheld_taxes, total_amount, digital_stamp, certificate_number, certificate, sat_seal, sat_certificate, fiscal_folio, stamp_datetime, expedition_place, export_operation, confirmation, source_filename, xml_file_size, confidence_score, processing_time, processing_status) VALUES (?, ?, ?, ?, ?, ?, ?, ?, ?, ?, ?, ?, ?, ?, ?, ?, ?, ?, ?, ?, ?, ?, ?, ?, ?, ?, ?, ?, ?, ?, ?, ?, ?, ?, ?, ?, ?, ?, ?, ?, ?, ?, ?, ?, ?, ?, ?)]
[parameters: ('AB31CFD1-C61A-4637-A9C0-71B7C676AAA8', None, '50389', 'I', '4.0', '2025-06-10 00:42:09.105549', None, '2025-06-10 00:42:09.139907', '2025-06-10 00:42:09.139907', 'PIVV******RR4', 'VANESSA IVON PIÑUELAS VERDUGO', '612', None, None, None, 'YUGY******FK4', 'YASSER YUSSIF GONZALEZ', '23300', None, None, None, '99', None, 'PPD', None, 'MXN', 1.0, 1109.9, 0.0, 6.9, 0.0, 1116.8, 'aQfQopzRPLxulkiqjktVYxiduTpNrSwDB4dZP7PvCBUrQRR/5XUvRHyKPVX61EQKhLEtbj5g2e14t+RfCi5th3rxKRsSQZatC8ftc9fPXtn6MoSywmSTLDz8MnUjHtvHfEd2AHn3UshIjneQOCBbR ... (46 characters truncated) ... rrDojl3CGXeigZqDuSgBIdy6YMzLYlsUN1AomwMjwQI3a61pF3RBsIfZwnmvRHsUa0EOLHc+F5GQJHpWDynRz3zuGjxjQal24uz2XiSUXLqjGYLo3CrxBe+XbGJ8/wXE5Z5POE3AJ0QuszTCyyw==', '00001000000705018977', None, 'gJTwCIW7z1Ill/xpC6f2EBZYisQKGq7LKRPZyZ7Oq8fC074zWIb8qCpOIKEUNeEWBE1V+7PUvxSA44RrhqKq6+k1RZojgIrm8xqPO4uiItCDVFwlPK0Vyi6wUJNfrgnx2yCLped62LdAxyQrL+Gc4 ... (46 characters truncated) ... yPIGMDuKo3U+wIpQ2QhnK4R1ZFm/foyowBdQ8XzMXH2tw/9L1PSn1rUIZC0RpV7kOfmS5WQXsIOpkA6VQnRH7cNVBjC3XgOU1wyxKYRq9QBpE2aCA1wqm4qvDaofIEgXZRUjWTGBaz/JUfWpjoQ==', None, 'AB31CFD1-C61A-4637-A9C0-71B7C676AAA8', '2025-06-10 00:42:09.115910', None, None, None, 'AB31CFD1-C61A-4637-A9C0-71B7C676AAA8.xml', 10794, None, None, 'processed')]
(Background on this error at: https://sqlalche.me/e/20/gkpj)
2025-06-09 17:42:09,202 - src.processing.batch_processor - ERROR - File: batch_processor.py - File: batch_processor.py - File: batch_processor.py - File: batch_processor.py - File: batch_processor.py - [ERROR] Failed to process AB31CFD1-C61A-4637-A9C0-71B7C676AAA8.xml: Failed to save invoice to database
2025-06-12 18:38:43,184 - src.processing.gemini_classifier - ERROR - File: gemini_classifier.py - File: gemini_classifier.py - File: gemini_classifier.py - File: gemini_classifier.py - File: gemini_classifier.py - Gemini API failed after 3 attempts: 400 API key not valid. Please pass a valid API key. [reason: "API_KEY_INVALID"
domain: "googleapis.com"
metadata {
  key: "service"
  value: "generativelanguage.googleapis.com"
}
, locale: "en-US"
message: "API key not valid. Please pass a valid API key."
]
2025-06-12 18:38:43,188 - src.processing.gemini_classifier - ERROR - File: gemini_classifier.py - File: gemini_classifier.py - File: gemini_classifier.py - File: gemini_classifier.py - File: gemini_classifier.py - Classification failed for sku_7e77527c_30111601_cemento_gris_holcim_25kg: Gemini API failed after 3 attempts: 400 API key not valid. Please pass a valid API key. [reason: "API_KEY_INVALID"
domain: "googleapis.com"
metadata {
  key: "service"
  value: "generativelanguage.googleapis.com"
}
, locale: "en-US"
message: "API key not valid. Please pass a valid API key."
]
2025-06-12 18:38:46,888 - src.processing.gemini_classifier - ERROR - File: gemini_classifier.py - File: gemini_classifier.py - File: gemini_classifier.py - File: gemini_classifier.py - File: gemini_classifier.py - Gemini API failed after 3 attempts: 400 API key not valid. Please pass a valid API key. [reason: "API_KEY_INVALID"
domain: "googleapis.com"
metadata {
  key: "service"
  value: "generativelanguage.googleapis.com"
}
, locale: "en-US"
message: "API key not valid. Please pass a valid API key."
]
2025-06-12 18:38:46,899 - src.processing.gemini_classifier - ERROR - File: gemini_classifier.py - File: gemini_classifier.py - File: gemini_classifier.py - File: gemini_classifier.py - File: gemini_classifier.py - Classification failed for sku_14c77eea_50414500_kale: Gemini API failed after 3 attempts: 400 API key not valid. Please pass a valid API key. [reason: "API_KEY_INVALID"
domain: "googleapis.com"
metadata {
  key: "service"
  value: "generativelanguage.googleapis.com"
}
, locale: "en-US"
message: "API key not valid. Please pass a valid API key."
]
2025-07-10 12:14:12,717 - src.data.database - ERROR - File: database.py - File: database.py - File: database.py - File: database.py - File: database.py - Database session error: 'datetime.datetime' object has no attribute 'strip'
2025-07-10 12:14:12,720 - src.processing.batch_processor - ERROR - File: batch_processor.py - File: batch_processor.py - File: batch_processor.py - File: batch_processor.py - File: batch_processor.py - Database save failed: 'datetime.datetime' object has no attribute 'strip'
2025-07-10 12:14:12,722 - src.processing.batch_processor - ERROR - File: batch_processor.py - File: batch_processor.py - File: batch_processor.py - File: batch_processor.py - File: batch_processor.py - [ERROR] Failed to process 04061ab5-c50d-46f3-aba1-148bdc5c2333.xml: Failed to save invoice to database
2025-07-10 12:14:23,799 - src.data.database - ERROR - File: database.py - File: database.py - File: database.py - File: database.py - File: database.py - Database session error: 'datetime.datetime' object has no attribute 'strip'
2025-07-10 12:14:23,803 - src.processing.batch_processor - ERROR - File: batch_processor.py - File: batch_processor.py - File: batch_processor.py - File: batch_processor.py - File: batch_processor.py - Database save failed: 'datetime.datetime' object has no attribute 'strip'
2025-07-10 12:14:23,803 - src.processing.batch_processor - ERROR - File: batch_processor.py - File: batch_processor.py - File: batch_processor.py - File: batch_processor.py - File: batch_processor.py - [ERROR] Failed to process 0781DA3A-D65A-4B8C-827C-104B8D3F52F8.xml: Failed to save invoice to database
2025-07-10 12:14:27,607 - src.data.database - ERROR - File: database.py - File: database.py - File: database.py - File: database.py - File: database.py - Database session error: 'datetime.datetime' object has no attribute 'strip'
2025-07-10 12:14:27,607 - src.processing.batch_processor - ERROR - File: batch_processor.py - File: batch_processor.py - File: batch_processor.py - File: batch_processor.py - File: batch_processor.py - Database save failed: 'datetime.datetime' object has no attribute 'strip'
2025-07-10 12:14:27,607 - src.processing.batch_processor - ERROR - File: batch_processor.py - File: batch_processor.py - File: batch_processor.py - File: batch_processor.py - File: batch_processor.py - [ERROR] Failed to process 0F8A00BD-D32D-4F47-851A-F1EBC7AEE7B3.xml: Failed to save invoice to database
2025-07-10 12:14:29,257 - src.data.database - ERROR - File: database.py - File: database.py - File: database.py - File: database.py - File: database.py - Database session error: 'datetime.datetime' object has no attribute 'strip'
2025-07-10 12:14:29,259 - src.processing.batch_processor - ERROR - File: batch_processor.py - File: batch_processor.py - File: batch_processor.py - File: batch_processor.py - File: batch_processor.py - Database save failed: 'datetime.datetime' object has no attribute 'strip'
2025-07-10 12:14:29,260 - src.processing.batch_processor - ERROR - File: batch_processor.py - File: batch_processor.py - File: batch_processor.py - File: batch_processor.py - File: batch_processor.py - [ERROR] Failed to process 109BCCAF-DC6E-4C71-B0B4-468D3D894E02.xml: Failed to save invoice to database
2025-07-10 12:14:34,463 - src.data.database - ERROR - File: database.py - File: database.py - File: database.py - File: database.py - File: database.py - Database session error: 'datetime.datetime' object has no attribute 'strip'
2025-07-10 12:14:34,466 - src.processing.batch_processor - ERROR - File: batch_processor.py - File: batch_processor.py - File: batch_processor.py - File: batch_processor.py - File: batch_processor.py - Database save failed: 'datetime.datetime' object has no attribute 'strip'
2025-07-10 12:14:34,466 - src.processing.batch_processor - ERROR - File: batch_processor.py - File: batch_processor.py - File: batch_processor.py - File: batch_processor.py - File: batch_processor.py - [ERROR] Failed to process 14EC3352-40A7-4008-9A6F-882A27D4E343.xml: Failed to save invoice to database
2025-07-10 12:14:44,804 - src.data.database - ERROR - File: database.py - File: database.py - File: database.py - File: database.py - File: database.py - Database session error: 'datetime.datetime' object has no attribute 'strip'
2025-07-10 12:14:44,807 - src.processing.batch_processor - ERROR - File: batch_processor.py - File: batch_processor.py - File: batch_processor.py - File: batch_processor.py - File: batch_processor.py - Database save failed: 'datetime.datetime' object has no attribute 'strip'
2025-07-10 12:14:44,810 - src.processing.batch_processor - ERROR - File: batch_processor.py - File: batch_processor.py - File: batch_processor.py - File: batch_processor.py - File: batch_processor.py - [ERROR] Failed to process 1C3D24B8-AE7B-4C38-9F3A-39BA15225883.xml: Failed to save invoice to database
2025-07-10 12:14:48,498 - src.data.database - ERROR - File: database.py - File: database.py - File: database.py - File: database.py - File: database.py - Database session error: 'datetime.datetime' object has no attribute 'strip'
2025-07-10 12:14:48,499 - src.processing.batch_processor - ERROR - File: batch_processor.py - File: batch_processor.py - File: batch_processor.py - File: batch_processor.py - File: batch_processor.py - Database save failed: 'datetime.datetime' object has no attribute 'strip'
2025-07-10 12:14:48,499 - src.processing.batch_processor - ERROR - File: batch_processor.py - File: batch_processor.py - File: batch_processor.py - File: batch_processor.py - File: batch_processor.py - [ERROR] Failed to process 285452E8-72C8-4188-BB11-4170D357CC9B.xml: Failed to save invoice to database
2025-07-10 12:14:51,624 - src.data.database - ERROR - File: database.py - File: database.py - File: database.py - File: database.py - File: database.py - Database session error: 'datetime.datetime' object has no attribute 'strip'
2025-07-10 12:14:51,624 - src.processing.batch_processor - ERROR - File: batch_processor.py - File: batch_processor.py - File: batch_processor.py - File: batch_processor.py - File: batch_processor.py - Database save failed: 'datetime.datetime' object has no attribute 'strip'
2025-07-10 12:14:51,627 - src.processing.batch_processor - ERROR - File: batch_processor.py - File: batch_processor.py - File: batch_processor.py - File: batch_processor.py - File: batch_processor.py - [ERROR] Failed to process 29E5CB35-0ED4-4048-8BBC-EAB4381BAD9F.xml: Failed to save invoice to database
2025-07-10 12:14:53,365 - src.data.database - ERROR - File: database.py - File: database.py - File: database.py - File: database.py - File: database.py - Database session error: 'datetime.datetime' object has no attribute 'strip'
2025-07-10 12:14:53,367 - src.processing.batch_processor - ERROR - File: batch_processor.py - File: batch_processor.py - File: batch_processor.py - File: batch_processor.py - File: batch_processor.py - Database save failed: 'datetime.datetime' object has no attribute 'strip'
2025-07-10 12:14:53,371 - src.processing.batch_processor - ERROR - File: batch_processor.py - File: batch_processor.py - File: batch_processor.py - File: batch_processor.py - File: batch_processor.py - [ERROR] Failed to process 2DE2FB0E-380D-4DB4-801D-2DA95A989235.xml: Failed to save invoice to database
2025-07-10 12:15:08,936 - src.data.database - ERROR - File: database.py - File: database.py - File: database.py - File: database.py - File: database.py - Database session error: 'datetime.datetime' object has no attribute 'strip'
2025-07-10 12:15:08,941 - src.processing.batch_processor - ERROR - File: batch_processor.py - File: batch_processor.py - File: batch_processor.py - File: batch_processor.py - File: batch_processor.py - Database save failed: 'datetime.datetime' object has no attribute 'strip'
2025-07-10 12:15:08,943 - src.processing.batch_processor - ERROR - File: batch_processor.py - File: batch_processor.py - File: batch_processor.py - File: batch_processor.py - File: batch_processor.py - [ERROR] Failed to process 2b474195-45f6-4055-9848-2ca0f8e44f7a.xml: Failed to save invoice to database
2025-07-10 12:15:10,875 - src.data.database - ERROR - File: database.py - File: database.py - File: database.py - File: database.py - File: database.py - Database session error: 'datetime.datetime' object has no attribute 'strip'
2025-07-10 12:15:10,880 - src.processing.batch_processor - ERROR - File: batch_processor.py - File: batch_processor.py - File: batch_processor.py - File: batch_processor.py - File: batch_processor.py - Database save failed: 'datetime.datetime' object has no attribute 'strip'
2025-07-10 12:15:10,880 - src.processing.batch_processor - ERROR - File: batch_processor.py - File: batch_processor.py - File: batch_processor.py - File: batch_processor.py - File: batch_processor.py - [ERROR] Failed to process 329AE5C9-CDB1-434B-B2FC-FFC6932E8DE8.xml: Failed to save invoice to database
2025-07-10 12:15:12,604 - src.data.database - ERROR - File: database.py - File: database.py - File: database.py - File: database.py - File: database.py - Database session error: 'datetime.datetime' object has no attribute 'strip'
2025-07-10 12:15:12,607 - src.processing.batch_processor - ERROR - File: batch_processor.py - File: batch_processor.py - File: batch_processor.py - File: batch_processor.py - File: batch_processor.py - Database save failed: 'datetime.datetime' object has no attribute 'strip'
2025-07-10 12:15:12,613 - src.processing.batch_processor - ERROR - File: batch_processor.py - File: batch_processor.py - File: batch_processor.py - File: batch_processor.py - File: batch_processor.py - [ERROR] Failed to process 3F78A759-2E37-432D-A905-710FAA2EA1F4.xml: Failed to save invoice to database
2025-07-10 12:15:15,826 - src.data.database - ERROR - File: database.py - File: database.py - File: database.py - File: database.py - File: database.py - Database session error: 'datetime.datetime' object has no attribute 'strip'
2025-07-10 12:15:15,827 - src.processing.batch_processor - ERROR - File: batch_processor.py - File: batch_processor.py - File: batch_processor.py - File: batch_processor.py - File: batch_processor.py - Database save failed: 'datetime.datetime' object has no attribute 'strip'
2025-07-10 12:15:15,828 - src.processing.batch_processor - ERROR - File: batch_processor.py - File: batch_processor.py - File: batch_processor.py - File: batch_processor.py - File: batch_processor.py - [ERROR] Failed to process 57D8103E-6131-4D36-A212-4039A44C74EA.xml: Failed to save invoice to database
2025-07-10 12:15:23,538 - src.data.database - ERROR - File: database.py - File: database.py - File: database.py - File: database.py - File: database.py - Database session error: 'datetime.datetime' object has no attribute 'strip'
2025-07-10 12:15:23,538 - src.processing.batch_processor - ERROR - File: batch_processor.py - File: batch_processor.py - File: batch_processor.py - File: batch_processor.py - File: batch_processor.py - Database save failed: 'datetime.datetime' object has no attribute 'strip'
2025-07-10 12:15:23,540 - src.processing.batch_processor - ERROR - File: batch_processor.py - File: batch_processor.py - File: batch_processor.py - File: batch_processor.py - File: batch_processor.py - [ERROR] Failed to process 5A6AB4C5-995F-46F3-B7D7-BED6C80AEFD6.xml: Failed to save invoice to database
2025-07-10 12:15:26,867 - src.data.database - ERROR - File: database.py - File: database.py - File: database.py - File: database.py - File: database.py - Database session error: 'datetime.datetime' object has no attribute 'strip'
2025-07-10 12:15:26,870 - src.processing.batch_processor - ERROR - File: batch_processor.py - File: batch_processor.py - File: batch_processor.py - File: batch_processor.py - File: batch_processor.py - Database save failed: 'datetime.datetime' object has no attribute 'strip'
2025-07-10 12:15:26,872 - src.processing.batch_processor - ERROR - File: batch_processor.py - File: batch_processor.py - File: batch_processor.py - File: batch_processor.py - File: batch_processor.py - [ERROR] Failed to process 670587E2-F5A5-4A27-8F10-58F5C605B1EC.xml: Failed to save invoice to database
2025-07-10 12:15:26,932 - src.data.database - ERROR - File: database.py - File: database.py - File: database.py - File: database.py - File: database.py - Database session error: 'datetime.datetime' object has no attribute 'strip'
2025-07-10 12:15:26,933 - src.processing.batch_processor - ERROR - File: batch_processor.py - File: batch_processor.py - File: batch_processor.py - File: batch_processor.py - File: batch_processor.py - Database save failed: 'datetime.datetime' object has no attribute 'strip'
2025-07-10 12:15:26,935 - src.processing.batch_processor - ERROR - File: batch_processor.py - File: batch_processor.py - File: batch_processor.py - File: batch_processor.py - File: batch_processor.py - [ERROR] Failed to process 67F16CA4-C800-409C-97D7-5B366AE5E6D4.xml: Failed to save invoice to database
2025-07-10 12:15:28,696 - src.data.database - ERROR - File: database.py - File: database.py - File: database.py - File: database.py - File: database.py - Database session error: 'datetime.datetime' object has no attribute 'strip'
2025-07-10 12:15:28,698 - src.processing.batch_processor - ERROR - File: batch_processor.py - File: batch_processor.py - File: batch_processor.py - File: batch_processor.py - File: batch_processor.py - Database save failed: 'datetime.datetime' object has no attribute 'strip'
2025-07-10 12:15:28,699 - src.processing.batch_processor - ERROR - File: batch_processor.py - File: batch_processor.py - File: batch_processor.py - File: batch_processor.py - File: batch_processor.py - [ERROR] Failed to process 6F0697AD-B159-42DD-8CEC-3E553EA1C944.xml: Failed to save invoice to database
2025-07-10 12:15:28,849 - src.data.database - ERROR - File: database.py - File: database.py - File: database.py - File: database.py - File: database.py - Database session error: 'datetime.datetime' object has no attribute 'strip'
2025-07-10 12:15:28,852 - src.processing.batch_processor - ERROR - File: batch_processor.py - File: batch_processor.py - File: batch_processor.py - File: batch_processor.py - File: batch_processor.py - Database save failed: 'datetime.datetime' object has no attribute 'strip'
2025-07-10 12:15:28,857 - src.processing.batch_processor - ERROR - File: batch_processor.py - File: batch_processor.py - File: batch_processor.py - File: batch_processor.py - File: batch_processor.py - [ERROR] Failed to process 6F69F65C-0943-4D1B-91AF-3102A0D41C4D.xml: Failed to save invoice to database
2025-07-10 12:15:43,178 - src.data.database - ERROR - File: database.py - File: database.py - File: database.py - File: database.py - File: database.py - Database session error: 'datetime.datetime' object has no attribute 'strip'
2025-07-10 12:15:43,179 - src.processing.batch_processor - ERROR - File: batch_processor.py - File: batch_processor.py - File: batch_processor.py - File: batch_processor.py - File: batch_processor.py - Database save failed: 'datetime.datetime' object has no attribute 'strip'
2025-07-10 12:15:43,182 - src.processing.batch_processor - ERROR - File: batch_processor.py - File: batch_processor.py - File: batch_processor.py - File: batch_processor.py - File: batch_processor.py - [ERROR] Failed to process 7579E18A-2439-4BFF-A0F7-96B110FB3A40.xml: Failed to save invoice to database
2025-07-10 12:15:43,374 - src.data.database - ERROR - File: database.py - File: database.py - File: database.py - File: database.py - File: database.py - Database session error: 'datetime.datetime' object has no attribute 'strip'
2025-07-10 12:15:43,377 - src.processing.batch_processor - ERROR - File: batch_processor.py - File: batch_processor.py - File: batch_processor.py - File: batch_processor.py - File: batch_processor.py - Database save failed: 'datetime.datetime' object has no attribute 'strip'
2025-07-10 12:15:43,379 - src.processing.batch_processor - ERROR - File: batch_processor.py - File: batch_processor.py - File: batch_processor.py - File: batch_processor.py - File: batch_processor.py - [ERROR] Failed to process 7CB73D45-AF0A-434F-A1E0-902AC8314AC1.xml: Failed to save invoice to database
2025-07-10 12:15:53,950 - src.data.database - ERROR - File: database.py - File: database.py - File: database.py - File: database.py - File: database.py - Database session error: 'datetime.datetime' object has no attribute 'strip'
2025-07-10 12:15:53,952 - src.processing.batch_processor - ERROR - File: batch_processor.py - File: batch_processor.py - File: batch_processor.py - File: batch_processor.py - File: batch_processor.py - Database save failed: 'datetime.datetime' object has no attribute 'strip'
2025-07-10 12:15:53,953 - src.processing.batch_processor - ERROR - File: batch_processor.py - File: batch_processor.py - File: batch_processor.py - File: batch_processor.py - File: batch_processor.py - [ERROR] Failed to process 7D2019DB-CD61-4600-8F65-DD44ADF4FC0E.xml: Failed to save invoice to database
2025-07-10 12:15:55,460 - src.data.database - ERROR - File: database.py - File: database.py - File: database.py - File: database.py - File: database.py - Database session error: 'datetime.datetime' object has no attribute 'strip'
2025-07-10 12:15:55,461 - src.processing.batch_processor - ERROR - File: batch_processor.py - File: batch_processor.py - File: batch_processor.py - File: batch_processor.py - File: batch_processor.py - Database save failed: 'datetime.datetime' object has no attribute 'strip'
2025-07-10 12:15:55,462 - src.processing.batch_processor - ERROR - File: batch_processor.py - File: batch_processor.py - File: batch_processor.py - File: batch_processor.py - File: batch_processor.py - [ERROR] Failed to process 7E6332A9-BF15-4F9F-BE4F-CEADDF154AD7.xml: Failed to save invoice to database
2025-07-10 12:15:55,538 - src.data.database - ERROR - File: database.py - File: database.py - File: database.py - File: database.py - File: database.py - Database session error: 'datetime.datetime' object has no attribute 'strip'
2025-07-10 12:15:55,540 - src.processing.batch_processor - ERROR - File: batch_processor.py - File: batch_processor.py - File: batch_processor.py - File: batch_processor.py - File: batch_processor.py - Database save failed: 'datetime.datetime' object has no attribute 'strip'
2025-07-10 12:15:55,541 - src.processing.batch_processor - ERROR - File: batch_processor.py - File: batch_processor.py - File: batch_processor.py - File: batch_processor.py - File: batch_processor.py - [ERROR] Failed to process 7EC2C80D-447B-41D7-A5D7-64B42CFE6860.xml: Failed to save invoice to database
2025-07-10 12:15:55,743 - src.data.database - ERROR - File: database.py - File: database.py - File: database.py - File: database.py - File: database.py - Database session error: 'datetime.datetime' object has no attribute 'strip'
2025-07-10 12:15:55,744 - src.processing.batch_processor - ERROR - File: batch_processor.py - File: batch_processor.py - File: batch_processor.py - File: batch_processor.py - File: batch_processor.py - Database save failed: 'datetime.datetime' object has no attribute 'strip'
2025-07-10 12:15:55,746 - src.processing.batch_processor - ERROR - File: batch_processor.py - File: batch_processor.py - File: batch_processor.py - File: batch_processor.py - File: batch_processor.py - [ERROR] Failed to process 86BDC7C8-B9C2-4FB8-952C-40A975B0E4D6.xml: Failed to save invoice to database
2025-07-10 12:15:58,711 - src.data.database - ERROR - File: database.py - File: database.py - File: database.py - File: database.py - File: database.py - Database session error: 'datetime.datetime' object has no attribute 'strip'
2025-07-10 12:15:58,712 - src.processing.batch_processor - ERROR - File: batch_processor.py - File: batch_processor.py - File: batch_processor.py - File: batch_processor.py - File: batch_processor.py - Database save failed: 'datetime.datetime' object has no attribute 'strip'
2025-07-10 12:15:58,715 - src.processing.batch_processor - ERROR - File: batch_processor.py - File: batch_processor.py - File: batch_processor.py - File: batch_processor.py - File: batch_processor.py - [ERROR] Failed to process 8AC2BFA4-8362-4291-B692-9C2D450198E4.xml: Failed to save invoice to database
2025-07-10 12:16:11,234 - src.data.database - ERROR - File: database.py - File: database.py - File: database.py - File: database.py - File: database.py - Database session error: 'datetime.datetime' object has no attribute 'strip'
2025-07-10 12:16:11,237 - src.processing.batch_processor - ERROR - File: batch_processor.py - File: batch_processor.py - File: batch_processor.py - File: batch_processor.py - File: batch_processor.py - Database save failed: 'datetime.datetime' object has no attribute 'strip'
2025-07-10 12:16:11,239 - src.processing.batch_processor - ERROR - File: batch_processor.py - File: batch_processor.py - File: batch_processor.py - File: batch_processor.py - File: batch_processor.py - [ERROR] Failed to process 8CCD00E8-8EAC-4926-BE8F-0B57C8856E84.xml: Failed to save invoice to database
2025-07-10 12:16:13,212 - src.data.database - ERROR - File: database.py - File: database.py - File: database.py - File: database.py - File: database.py - Database session error: 'datetime.datetime' object has no attribute 'strip'
2025-07-10 12:16:13,213 - src.processing.batch_processor - ERROR - File: batch_processor.py - File: batch_processor.py - File: batch_processor.py - File: batch_processor.py - File: batch_processor.py - Database save failed: 'datetime.datetime' object has no attribute 'strip'
2025-07-10 12:16:13,213 - src.processing.batch_processor - ERROR - File: batch_processor.py - File: batch_processor.py - File: batch_processor.py - File: batch_processor.py - File: batch_processor.py - [ERROR] Failed to process 978d18b7-b0c4-420d-9529-6c3eb2cac218.xml: Failed to save invoice to database
2025-07-10 12:16:13,318 - src.data.database - ERROR - File: database.py - File: database.py - File: database.py - File: database.py - File: database.py - Database session error: 'datetime.datetime' object has no attribute 'strip'
2025-07-10 12:16:13,319 - src.processing.batch_processor - ERROR - File: batch_processor.py - File: batch_processor.py - File: batch_processor.py - File: batch_processor.py - File: batch_processor.py - Database save failed: 'datetime.datetime' object has no attribute 'strip'
2025-07-10 12:16:13,320 - src.processing.batch_processor - ERROR - File: batch_processor.py - File: batch_processor.py - File: batch_processor.py - File: batch_processor.py - File: batch_processor.py - [ERROR] Failed to process 9B316DDF-0827-4012-B8E8-9C08161BF41B.xml: Failed to save invoice to database
2025-07-10 12:16:14,643 - src.data.database - ERROR - File: database.py - File: database.py - File: database.py - File: database.py - File: database.py - Database session error: 'datetime.datetime' object has no attribute 'strip'
2025-07-10 12:16:14,646 - src.processing.batch_processor - ERROR - File: batch_processor.py - File: batch_processor.py - File: batch_processor.py - File: batch_processor.py - File: batch_processor.py - Database save failed: 'datetime.datetime' object has no attribute 'strip'
2025-07-10 12:16:14,647 - src.processing.batch_processor - ERROR - File: batch_processor.py - File: batch_processor.py - File: batch_processor.py - File: batch_processor.py - File: batch_processor.py - [ERROR] Failed to process ACF5E9D9-459A-485E-A8DF-9A2E14F03941.xml: Failed to save invoice to database
2025-07-10 12:16:16,386 - src.data.database - ERROR - File: database.py - File: database.py - File: database.py - File: database.py - File: database.py - Database session error: 'datetime.datetime' object has no attribute 'strip'
2025-07-10 12:16:16,387 - src.processing.batch_processor - ERROR - File: batch_processor.py - File: batch_processor.py - File: batch_processor.py - File: batch_processor.py - File: batch_processor.py - Database save failed: 'datetime.datetime' object has no attribute 'strip'
2025-07-10 12:16:16,388 - src.processing.batch_processor - ERROR - File: batch_processor.py - File: batch_processor.py - File: batch_processor.py - File: batch_processor.py - File: batch_processor.py - [ERROR] Failed to process B696B7FF-E66C-46CF-A45D-D819C44431A3.xml: Failed to save invoice to database
2025-07-10 12:16:18,014 - src.data.database - ERROR - File: database.py - File: database.py - File: database.py - File: database.py - File: database.py - Database session error: 'datetime.datetime' object has no attribute 'strip'
2025-07-10 12:16:18,014 - src.processing.batch_processor - ERROR - File: batch_processor.py - File: batch_processor.py - File: batch_processor.py - File: batch_processor.py - File: batch_processor.py - Database save failed: 'datetime.datetime' object has no attribute 'strip'
2025-07-10 12:16:18,016 - src.processing.batch_processor - ERROR - File: batch_processor.py - File: batch_processor.py - File: batch_processor.py - File: batch_processor.py - File: batch_processor.py - [ERROR] Failed to process C8E39A35-3357-4C8F-AF22-534AFE703FEA.xml: Failed to save invoice to database
2025-07-10 12:16:22,677 - src.data.database - ERROR - File: database.py - File: database.py - File: database.py - File: database.py - File: database.py - Database session error: 'datetime.datetime' object has no attribute 'strip'
2025-07-10 12:16:22,678 - src.processing.batch_processor - ERROR - File: batch_processor.py - File: batch_processor.py - File: batch_processor.py - File: batch_processor.py - File: batch_processor.py - Database save failed: 'datetime.datetime' object has no attribute 'strip'
2025-07-10 12:16:22,679 - src.processing.batch_processor - ERROR - File: batch_processor.py - File: batch_processor.py - File: batch_processor.py - File: batch_processor.py - File: batch_processor.py - [ERROR] Failed to process DC82A272-2FA8-4F2F-A807-6B6F55BDF18E.xml: Failed to save invoice to database
2025-07-10 12:16:25,930 - src.data.database - ERROR - File: database.py - File: database.py - File: database.py - File: database.py - File: database.py - Database session error: 'datetime.datetime' object has no attribute 'strip'
2025-07-10 12:16:25,938 - src.processing.batch_processor - ERROR - File: batch_processor.py - File: batch_processor.py - File: batch_processor.py - File: batch_processor.py - File: batch_processor.py - Database save failed: 'datetime.datetime' object has no attribute 'strip'
2025-07-10 12:16:25,940 - src.processing.batch_processor - ERROR - File: batch_processor.py - File: batch_processor.py - File: batch_processor.py - File: batch_processor.py - File: batch_processor.py - [ERROR] Failed to process E11056BF-CB35-41B5-AF5B-CFB0E089A32E.xml: Failed to save invoice to database
2025-07-10 12:16:29,714 - src.data.database - ERROR - File: database.py - File: database.py - File: database.py - File: database.py - File: database.py - Database session error: 'datetime.datetime' object has no attribute 'strip'
2025-07-10 12:16:29,714 - src.processing.batch_processor - ERROR - File: batch_processor.py - File: batch_processor.py - File: batch_processor.py - File: batch_processor.py - File: batch_processor.py - Database save failed: 'datetime.datetime' object has no attribute 'strip'
2025-07-10 12:16:29,722 - src.processing.batch_processor - ERROR - File: batch_processor.py - File: batch_processor.py - File: batch_processor.py - File: batch_processor.py - File: batch_processor.py - [ERROR] Failed to process E3BAA208-BB42-49C5-9E72-D7702308F471.xml: Failed to save invoice to database
2025-07-10 12:16:31,118 - src.data.database - ERROR - File: database.py - File: database.py - File: database.py - File: database.py - File: database.py - Database session error: 'datetime.datetime' object has no attribute 'strip'
2025-07-10 12:16:31,124 - src.processing.batch_processor - ERROR - File: batch_processor.py - File: batch_processor.py - File: batch_processor.py - File: batch_processor.py - File: batch_processor.py - Database save failed: 'datetime.datetime' object has no attribute 'strip'
2025-07-10 12:16:31,125 - src.processing.batch_processor - ERROR - File: batch_processor.py - File: batch_processor.py - File: batch_processor.py - File: batch_processor.py - File: batch_processor.py - [ERROR] Failed to process E507A17F-A130-4C08-8B4F-0FD300D02C85.xml: Failed to save invoice to database
2025-07-10 12:16:32,981 - src.data.database - ERROR - File: database.py - File: database.py - File: database.py - File: database.py - File: database.py - Database session error: 'datetime.datetime' object has no attribute 'strip'
2025-07-10 12:16:32,983 - src.processing.batch_processor - ERROR - File: batch_processor.py - File: batch_processor.py - File: batch_processor.py - File: batch_processor.py - File: batch_processor.py - Database save failed: 'datetime.datetime' object has no attribute 'strip'
2025-07-10 12:16:32,983 - src.processing.batch_processor - ERROR - File: batch_processor.py - File: batch_processor.py - File: batch_processor.py - File: batch_processor.py - File: batch_processor.py - [ERROR] Failed to process EFCD0679-9CE8-400D-8869-9B9D2C51DE62.xml: Failed to save invoice to database
2025-07-10 12:16:38,134 - src.data.database - ERROR - File: database.py - File: database.py - File: database.py - File: database.py - File: database.py - Database session error: 'datetime.datetime' object has no attribute 'strip'
2025-07-10 12:16:38,134 - src.processing.batch_processor - ERROR - File: batch_processor.py - File: batch_processor.py - File: batch_processor.py - File: batch_processor.py - File: batch_processor.py - Database save failed: 'datetime.datetime' object has no attribute 'strip'
2025-07-10 12:16:38,142 - src.processing.batch_processor - ERROR - File: batch_processor.py - File: batch_processor.py - File: batch_processor.py - File: batch_processor.py - File: batch_processor.py - [ERROR] Failed to process FBDD0E56-11A1-49B9-95C2-FD243E95986B.xml: Failed to save invoice to database
2025-07-10 12:16:40,912 - src.data.database - ERROR - File: database.py - File: database.py - File: database.py - File: database.py - File: database.py - Database session error: 'datetime.datetime' object has no attribute 'strip'
2025-07-10 12:16:40,913 - src.processing.batch_processor - ERROR - File: batch_processor.py - File: batch_processor.py - File: batch_processor.py - File: batch_processor.py - File: batch_processor.py - Database save failed: 'datetime.datetime' object has no attribute 'strip'
2025-07-10 12:16:40,913 - src.processing.batch_processor - ERROR - File: batch_processor.py - File: batch_processor.py - File: batch_processor.py - File: batch_processor.py - File: batch_processor.py - [ERROR] Failed to process FDE6B84B-D0D2-481D-9F46-749D780FFFEE.xml: Failed to save invoice to database
2025-07-10 12:16:52,124 - src.data.database - ERROR - File: database.py - File: database.py - File: database.py - File: database.py - File: database.py - Database session error: 'datetime.datetime' object has no attribute 'strip'
2025-07-10 12:16:52,126 - src.processing.batch_processor - ERROR - File: batch_processor.py - File: batch_processor.py - File: batch_processor.py - File: batch_processor.py - File: batch_processor.py - Database save failed: 'datetime.datetime' object has no attribute 'strip'
2025-07-10 12:16:52,129 - src.processing.batch_processor - ERROR - File: batch_processor.py - File: batch_processor.py - File: batch_processor.py - File: batch_processor.py - File: batch_processor.py - [ERROR] Failed to process db7ca908-83b2-49ab-8c86-649a9b9ba470.xml: Failed to save invoice to database
2025-07-10 16:30:46,999 - src.data.database - ERROR - File: database.py - File: database.py - File: database.py - File: database.py - File: database.py - Database session error: 'datetime.datetime' object has no attribute 'strip'
2025-07-10 16:30:47,000 - src.processing.batch_processor - ERROR - File: batch_processor.py - File: batch_processor.py - File: batch_processor.py - File: batch_processor.py - File: batch_processor.py - Database save failed: 'datetime.datetime' object has no attribute 'strip'
2025-07-10 16:30:47,002 - src.processing.batch_processor - ERROR - File: batch_processor.py - File: batch_processor.py - File: batch_processor.py - File: batch_processor.py - File: batch_processor.py - [ERROR] Failed to process 04061ab5-c50d-46f3-aba1-148bdc5c2333.xml: Failed to save invoice to database
2025-07-10 16:30:56,433 - src.data.database - ERROR - File: database.py - File: database.py - File: database.py - File: database.py - File: database.py - Database session error: 'datetime.datetime' object has no attribute 'strip'
2025-07-10 16:30:56,434 - src.processing.batch_processor - ERROR - File: batch_processor.py - File: batch_processor.py - File: batch_processor.py - File: batch_processor.py - File: batch_processor.py - Database save failed: 'datetime.datetime' object has no attribute 'strip'
2025-07-10 16:30:56,435 - src.processing.batch_processor - ERROR - File: batch_processor.py - File: batch_processor.py - File: batch_processor.py - File: batch_processor.py - File: batch_processor.py - [ERROR] Failed to process 0781DA3A-D65A-4B8C-827C-104B8D3F52F8.xml: Failed to save invoice to database
2025-07-10 16:30:57,896 - src.data.database - ERROR - File: database.py - File: database.py - File: database.py - File: database.py - File: database.py - Database session error: 'datetime.datetime' object has no attribute 'strip'
2025-07-10 16:30:57,898 - src.processing.batch_processor - ERROR - File: batch_processor.py - File: batch_processor.py - File: batch_processor.py - File: batch_processor.py - File: batch_processor.py - Database save failed: 'datetime.datetime' object has no attribute 'strip'
2025-07-10 16:30:57,899 - src.processing.batch_processor - ERROR - File: batch_processor.py - File: batch_processor.py - File: batch_processor.py - File: batch_processor.py - File: batch_processor.py - [ERROR] Failed to process 109BCCAF-DC6E-4C71-B0B4-468D3D894E02.xml: Failed to save invoice to database
2025-07-10 16:31:02,304 - src.data.database - ERROR - File: database.py - File: database.py - File: database.py - File: database.py - File: database.py - Database session error: 'datetime.datetime' object has no attribute 'strip'
2025-07-10 16:31:02,320 - src.processing.batch_processor - ERROR - File: batch_processor.py - File: batch_processor.py - File: batch_processor.py - File: batch_processor.py - File: batch_processor.py - Database save failed: 'datetime.datetime' object has no attribute 'strip'
2025-07-10 16:31:02,320 - src.processing.batch_processor - ERROR - File: batch_processor.py - File: batch_processor.py - File: batch_processor.py - File: batch_processor.py - File: batch_processor.py - [ERROR] Failed to process 29E5CB35-0ED4-4048-8BBC-EAB4381BAD9F.xml: Failed to save invoice to database
2025-07-10 16:31:09,074 - src.data.database - ERROR - File: database.py - File: database.py - File: database.py - File: database.py - File: database.py - Database session error: 'datetime.datetime' object has no attribute 'strip'
2025-07-10 16:31:09,075 - src.processing.batch_processor - ERROR - File: batch_processor.py - File: batch_processor.py - File: batch_processor.py - File: batch_processor.py - File: batch_processor.py - Database save failed: 'datetime.datetime' object has no attribute 'strip'
2025-07-10 16:31:09,078 - src.processing.batch_processor - ERROR - File: batch_processor.py - File: batch_processor.py - File: batch_processor.py - File: batch_processor.py - File: batch_processor.py - [ERROR] Failed to process 5A6AB4C5-995F-46F3-B7D7-BED6C80AEFD6.xml: Failed to save invoice to database
2025-07-10 16:31:09,148 - src.data.database - ERROR - File: database.py - File: database.py - File: database.py - File: database.py - File: database.py - Database session error: 'datetime.datetime' object has no attribute 'strip'
2025-07-10 16:31:09,149 - src.processing.batch_processor - ERROR - File: batch_processor.py - File: batch_processor.py - File: batch_processor.py - File: batch_processor.py - File: batch_processor.py - Database save failed: 'datetime.datetime' object has no attribute 'strip'
2025-07-10 16:31:09,153 - src.processing.batch_processor - ERROR - File: batch_processor.py - File: batch_processor.py - File: batch_processor.py - File: batch_processor.py - File: batch_processor.py - [ERROR] Failed to process 7EC2C80D-447B-41D7-A5D7-64B42CFE6860.xml: Failed to save invoice to database
2025-07-10 16:31:09,195 - src.data.database - ERROR - File: database.py - File: database.py - File: database.py - File: database.py - File: database.py - Database session error: 'datetime.datetime' object has no attribute 'strip'
2025-07-10 16:31:09,198 - src.processing.batch_processor - ERROR - File: batch_processor.py - File: batch_processor.py - File: batch_processor.py - File: batch_processor.py - File: batch_processor.py - Database save failed: 'datetime.datetime' object has no attribute 'strip'
2025-07-10 16:31:09,199 - src.processing.batch_processor - ERROR - File: batch_processor.py - File: batch_processor.py - File: batch_processor.py - File: batch_processor.py - File: batch_processor.py - [ERROR] Failed to process 86BDC7C8-B9C2-4FB8-952C-40A975B0E4D6.xml: Failed to save invoice to database
2025-07-10 16:31:11,014 - src.data.database - ERROR - File: database.py - File: database.py - File: database.py - File: database.py - File: database.py - Database session error: 'datetime.datetime' object has no attribute 'strip'
2025-07-10 16:31:11,015 - src.processing.batch_processor - ERROR - File: batch_processor.py - File: batch_processor.py - File: batch_processor.py - File: batch_processor.py - File: batch_processor.py - Database save failed: 'datetime.datetime' object has no attribute 'strip'
2025-07-10 16:31:11,017 - src.processing.batch_processor - ERROR - File: batch_processor.py - File: batch_processor.py - File: batch_processor.py - File: batch_processor.py - File: batch_processor.py - [ERROR] Failed to process 978d18b7-b0c4-420d-9529-6c3eb2cac218.xml: Failed to save invoice to database
2025-07-10 16:31:15,197 - src.data.database - ERROR - File: database.py - File: database.py - File: database.py - File: database.py - File: database.py - Database session error: 'datetime.datetime' object has no attribute 'strip'
2025-07-10 16:31:15,200 - src.processing.batch_processor - ERROR - File: batch_processor.py - File: batch_processor.py - File: batch_processor.py - File: batch_processor.py - File: batch_processor.py - Database save failed: 'datetime.datetime' object has no attribute 'strip'
2025-07-10 16:31:15,202 - src.processing.batch_processor - ERROR - File: batch_processor.py - File: batch_processor.py - File: batch_processor.py - File: batch_processor.py - File: batch_processor.py - [ERROR] Failed to process B696B7FF-E66C-46CF-A45D-D819C44431A3.xml: Failed to save invoice to database
2025-07-10 16:31:19,395 - src.data.database - ERROR - File: database.py - File: database.py - File: database.py - File: database.py - File: database.py - Database session error: 'datetime.datetime' object has no attribute 'strip'
2025-07-10 16:31:19,397 - src.processing.batch_processor - ERROR - File: batch_processor.py - File: batch_processor.py - File: batch_processor.py - File: batch_processor.py - File: batch_processor.py - Database save failed: 'datetime.datetime' object has no attribute 'strip'
2025-07-10 16:31:19,398 - src.processing.batch_processor - ERROR - File: batch_processor.py - File: batch_processor.py - File: batch_processor.py - File: batch_processor.py - File: batch_processor.py - [ERROR] Failed to process DC82A272-2FA8-4F2F-A807-6B6F55BDF18E.xml: Failed to save invoice to database
2025-07-10 16:31:24,866 - src.data.database - ERROR - File: database.py - File: database.py - File: database.py - File: database.py - File: database.py - Database session error: 'datetime.datetime' object has no attribute 'strip'
2025-07-10 16:31:24,867 - src.processing.batch_processor - ERROR - File: batch_processor.py - File: batch_processor.py - File: batch_processor.py - File: batch_processor.py - File: batch_processor.py - Database save failed: 'datetime.datetime' object has no attribute 'strip'
2025-07-10 16:31:24,869 - src.processing.batch_processor - ERROR - File: batch_processor.py - File: batch_processor.py - File: batch_processor.py - File: batch_processor.py - File: batch_processor.py - [ERROR] Failed to process E11056BF-CB35-41B5-AF5B-CFB0E089A32E.xml: Failed to save invoice to database
2025-07-10 16:31:26,171 - src.data.database - ERROR - File: database.py - File: database.py - File: database.py - File: database.py - File: database.py - Database session error: 'datetime.datetime' object has no attribute 'strip'
2025-07-10 16:31:26,171 - src.processing.batch_processor - ERROR - File: batch_processor.py - File: batch_processor.py - File: batch_processor.py - File: batch_processor.py - File: batch_processor.py - Database save failed: 'datetime.datetime' object has no attribute 'strip'
2025-07-10 16:31:26,171 - src.processing.batch_processor - ERROR - File: batch_processor.py - File: batch_processor.py - File: batch_processor.py - File: batch_processor.py - File: batch_processor.py - [ERROR] Failed to process E507A17F-A130-4C08-8B4F-0FD300D02C85.xml: Failed to save invoice to database
2025-07-10 16:31:31,106 - src.data.database - ERROR - File: database.py - File: database.py - File: database.py - File: database.py - File: database.py - Database session error: 'datetime.datetime' object has no attribute 'strip'
2025-07-10 16:31:31,106 - src.processing.batch_processor - ERROR - File: batch_processor.py - File: batch_processor.py - File: batch_processor.py - File: batch_processor.py - File: batch_processor.py - Database save failed: 'datetime.datetime' object has no attribute 'strip'
2025-07-10 16:31:31,107 - src.processing.batch_processor - ERROR - File: batch_processor.py - File: batch_processor.py - File: batch_processor.py - File: batch_processor.py - File: batch_processor.py - [ERROR] Failed to process FBDD0E56-11A1-49B9-95C2-FD243E95986B.xml: Failed to save invoice to database
2025-07-10 16:31:33,754 - src.data.database - ERROR - File: database.py - File: database.py - File: database.py - File: database.py - File: database.py - Database session error: 'datetime.datetime' object has no attribute 'strip'
2025-07-10 16:31:33,755 - src.processing.batch_processor - ERROR - File: batch_processor.py - File: batch_processor.py - File: batch_processor.py - File: batch_processor.py - File: batch_processor.py - Database save failed: 'datetime.datetime' object has no attribute 'strip'
2025-07-10 16:31:33,757 - src.processing.batch_processor - ERROR - File: batch_processor.py - File: batch_processor.py - File: batch_processor.py - File: batch_processor.py - File: batch_processor.py - [ERROR] Failed to process FDE6B84B-D0D2-481D-9F46-749D780FFFEE.xml: Failed to save invoice to database
2025-07-10 16:31:42,996 - src.data.database - ERROR - File: database.py - File: database.py - File: database.py - File: database.py - File: database.py - Database session error: 'datetime.datetime' object has no attribute 'strip'
2025-07-10 16:31:42,999 - src.processing.batch_processor - ERROR - File: batch_processor.py - File: batch_processor.py - File: batch_processor.py - File: batch_processor.py - File: batch_processor.py - Database save failed: 'datetime.datetime' object has no attribute 'strip'
2025-07-10 16:31:42,999 - src.processing.batch_processor - ERROR - File: batch_processor.py - File: batch_processor.py - File: batch_processor.py - File: batch_processor.py - File: batch_processor.py - [ERROR] Failed to process db7ca908-83b2-49ab-8c86-649a9b9ba470.xml: Failed to save invoice to database
2025-07-10 16:34:14,317 - src.data.database - ERROR - File: database.py - File: database.py - File: database.py - File: database.py - File: database.py - Database session error: 'datetime.datetime' object has no attribute 'strip'
2025-07-10 16:34:14,319 - src.processing.batch_processor - ERROR - File: batch_processor.py - File: batch_processor.py - File: batch_processor.py - File: batch_processor.py - File: batch_processor.py - Database save failed: 'datetime.datetime' object has no attribute 'strip'
2025-07-10 16:34:14,319 - src.processing.batch_processor - ERROR - File: batch_processor.py - File: batch_processor.py - File: batch_processor.py - File: batch_processor.py - File: batch_processor.py - [ERROR] Failed to process 0F8A00BD-D32D-4F47-851A-F1EBC7AEE7B3.xml: Failed to save invoice to database
2025-07-10 16:34:18,977 - src.data.database - ERROR - File: database.py - File: database.py - File: database.py - File: database.py - File: database.py - Database session error: 'datetime.datetime' object has no attribute 'strip'
2025-07-10 16:34:18,982 - src.processing.batch_processor - ERROR - File: batch_processor.py - File: batch_processor.py - File: batch_processor.py - File: batch_processor.py - File: batch_processor.py - Database save failed: 'datetime.datetime' object has no attribute 'strip'
2025-07-10 16:34:18,984 - src.processing.batch_processor - ERROR - File: batch_processor.py - File: batch_processor.py - File: batch_processor.py - File: batch_processor.py - File: batch_processor.py - [ERROR] Failed to process 14EC3352-40A7-4008-9A6F-882A27D4E343.xml: Failed to save invoice to database
2025-07-10 16:34:30,912 - src.data.database - ERROR - File: database.py - File: database.py - File: database.py - File: database.py - File: database.py - Database session error: 'datetime.datetime' object has no attribute 'strip'
2025-07-10 16:34:30,913 - src.processing.batch_processor - ERROR - File: batch_processor.py - File: batch_processor.py - File: batch_processor.py - File: batch_processor.py - File: batch_processor.py - Database save failed: 'datetime.datetime' object has no attribute 'strip'
2025-07-10 16:34:30,913 - src.processing.batch_processor - ERROR - File: batch_processor.py - File: batch_processor.py - File: batch_processor.py - File: batch_processor.py - File: batch_processor.py - [ERROR] Failed to process 1C3D24B8-AE7B-4C38-9F3A-39BA15225883.xml: Failed to save invoice to database
2025-07-10 16:34:34,522 - src.data.database - ERROR - File: database.py - File: database.py - File: database.py - File: database.py - File: database.py - Database session error: 'datetime.datetime' object has no attribute 'strip'
2025-07-10 16:34:34,524 - src.processing.batch_processor - ERROR - File: batch_processor.py - File: batch_processor.py - File: batch_processor.py - File: batch_processor.py - File: batch_processor.py - Database save failed: 'datetime.datetime' object has no attribute 'strip'
2025-07-10 16:34:34,525 - src.processing.batch_processor - ERROR - File: batch_processor.py - File: batch_processor.py - File: batch_processor.py - File: batch_processor.py - File: batch_processor.py - [ERROR] Failed to process 285452E8-72C8-4188-BB11-4170D357CC9B.xml: Failed to save invoice to database
2025-07-10 16:34:36,242 - src.data.database - ERROR - File: database.py - File: database.py - File: database.py - File: database.py - File: database.py - Database session error: 'datetime.datetime' object has no attribute 'strip'
2025-07-10 16:34:36,246 - src.processing.batch_processor - ERROR - File: batch_processor.py - File: batch_processor.py - File: batch_processor.py - File: batch_processor.py - File: batch_processor.py - Database save failed: 'datetime.datetime' object has no attribute 'strip'
2025-07-10 16:34:36,248 - src.processing.batch_processor - ERROR - File: batch_processor.py - File: batch_processor.py - File: batch_processor.py - File: batch_processor.py - File: batch_processor.py - [ERROR] Failed to process 2DE2FB0E-380D-4DB4-801D-2DA95A989235.xml: Failed to save invoice to database
2025-07-10 16:34:50,082 - src.data.database - ERROR - File: database.py - File: database.py - File: database.py - File: database.py - File: database.py - Database session error: 'datetime.datetime' object has no attribute 'strip'
2025-07-10 16:34:50,084 - src.processing.batch_processor - ERROR - File: batch_processor.py - File: batch_processor.py - File: batch_processor.py - File: batch_processor.py - File: batch_processor.py - Database save failed: 'datetime.datetime' object has no attribute 'strip'
2025-07-10 16:34:50,087 - src.processing.batch_processor - ERROR - File: batch_processor.py - File: batch_processor.py - File: batch_processor.py - File: batch_processor.py - File: batch_processor.py - [ERROR] Failed to process 2b474195-45f6-4055-9848-2ca0f8e44f7a.xml: Failed to save invoice to database
2025-07-10 16:34:51,548 - src.data.database - ERROR - File: database.py - File: database.py - File: database.py - File: database.py - File: database.py - Database session error: 'datetime.datetime' object has no attribute 'strip'
2025-07-10 16:34:51,549 - src.processing.batch_processor - ERROR - File: batch_processor.py - File: batch_processor.py - File: batch_processor.py - File: batch_processor.py - File: batch_processor.py - Database save failed: 'datetime.datetime' object has no attribute 'strip'
2025-07-10 16:34:51,551 - src.processing.batch_processor - ERROR - File: batch_processor.py - File: batch_processor.py - File: batch_processor.py - File: batch_processor.py - File: batch_processor.py - [ERROR] Failed to process 329AE5C9-CDB1-434B-B2FC-FFC6932E8DE8.xml: Failed to save invoice to database
2025-07-10 16:34:55,717 - src.data.database - ERROR - File: database.py - File: database.py - File: database.py - File: database.py - File: database.py - Database session error: 'datetime.datetime' object has no attribute 'strip'
2025-07-10 16:34:55,719 - src.processing.batch_processor - ERROR - File: batch_processor.py - File: batch_processor.py - File: batch_processor.py - File: batch_processor.py - File: batch_processor.py - Database save failed: 'datetime.datetime' object has no attribute 'strip'
2025-07-10 16:34:55,721 - src.processing.batch_processor - ERROR - File: batch_processor.py - File: batch_processor.py - File: batch_processor.py - File: batch_processor.py - File: batch_processor.py - [ERROR] Failed to process 3F78A759-2E37-432D-A905-710FAA2EA1F4.xml: Failed to save invoice to database
2025-07-10 16:35:00,428 - src.data.database - ERROR - File: database.py - File: database.py - File: database.py - File: database.py - File: database.py - Database session error: 'datetime.datetime' object has no attribute 'strip'
2025-07-10 16:35:00,430 - src.processing.batch_processor - ERROR - File: batch_processor.py - File: batch_processor.py - File: batch_processor.py - File: batch_processor.py - File: batch_processor.py - Database save failed: 'datetime.datetime' object has no attribute 'strip'
2025-07-10 16:35:00,431 - src.processing.batch_processor - ERROR - File: batch_processor.py - File: batch_processor.py - File: batch_processor.py - File: batch_processor.py - File: batch_processor.py - [ERROR] Failed to process 57D8103E-6131-4D36-A212-4039A44C74EA.xml: Failed to save invoice to database
2025-07-10 16:35:03,548 - src.data.database - ERROR - File: database.py - File: database.py - File: database.py - File: database.py - File: database.py - Database session error: 'datetime.datetime' object has no attribute 'strip'
2025-07-10 16:35:03,551 - src.processing.batch_processor - ERROR - File: batch_processor.py - File: batch_processor.py - File: batch_processor.py - File: batch_processor.py - File: batch_processor.py - Database save failed: 'datetime.datetime' object has no attribute 'strip'
2025-07-10 16:35:03,552 - src.processing.batch_processor - ERROR - File: batch_processor.py - File: batch_processor.py - File: batch_processor.py - File: batch_processor.py - File: batch_processor.py - [ERROR] Failed to process 670587E2-F5A5-4A27-8F10-58F5C605B1EC.xml: Failed to save invoice to database
2025-07-10 16:35:03,614 - src.data.database - ERROR - File: database.py - File: database.py - File: database.py - File: database.py - File: database.py - Database session error: 'datetime.datetime' object has no attribute 'strip'
2025-07-10 16:35:03,615 - src.processing.batch_processor - ERROR - File: batch_processor.py - File: batch_processor.py - File: batch_processor.py - File: batch_processor.py - File: batch_processor.py - Database save failed: 'datetime.datetime' object has no attribute 'strip'
2025-07-10 16:35:03,616 - src.processing.batch_processor - ERROR - File: batch_processor.py - File: batch_processor.py - File: batch_processor.py - File: batch_processor.py - File: batch_processor.py - [ERROR] Failed to process 67F16CA4-C800-409C-97D7-5B366AE5E6D4.xml: Failed to save invoice to database
2025-07-10 16:35:06,574 - src.data.database - ERROR - File: database.py - File: database.py - File: database.py - File: database.py - File: database.py - Database session error: 'datetime.datetime' object has no attribute 'strip'
2025-07-10 16:35:06,576 - src.processing.batch_processor - ERROR - File: batch_processor.py - File: batch_processor.py - File: batch_processor.py - File: batch_processor.py - File: batch_processor.py - Database save failed: 'datetime.datetime' object has no attribute 'strip'
2025-07-10 16:35:06,578 - src.processing.batch_processor - ERROR - File: batch_processor.py - File: batch_processor.py - File: batch_processor.py - File: batch_processor.py - File: batch_processor.py - [ERROR] Failed to process 6F0697AD-B159-42DD-8CEC-3E553EA1C944.xml: Failed to save invoice to database
2025-07-10 16:35:09,617 - src.data.database - ERROR - File: database.py - File: database.py - File: database.py - File: database.py - File: database.py - Database session error: 'datetime.datetime' object has no attribute 'strip'
2025-07-10 16:35:09,621 - src.processing.batch_processor - ERROR - File: batch_processor.py - File: batch_processor.py - File: batch_processor.py - File: batch_processor.py - File: batch_processor.py - Database save failed: 'datetime.datetime' object has no attribute 'strip'
2025-07-10 16:35:09,621 - src.processing.batch_processor - ERROR - File: batch_processor.py - File: batch_processor.py - File: batch_processor.py - File: batch_processor.py - File: batch_processor.py - [ERROR] Failed to process 6F69F65C-0943-4D1B-91AF-3102A0D41C4D.xml: Failed to save invoice to database
2025-07-10 16:35:23,523 - src.data.database - ERROR - File: database.py - File: database.py - File: database.py - File: database.py - File: database.py - Database session error: 'datetime.datetime' object has no attribute 'strip'
2025-07-10 16:35:23,527 - src.processing.batch_processor - ERROR - File: batch_processor.py - File: batch_processor.py - File: batch_processor.py - File: batch_processor.py - File: batch_processor.py - Database save failed: 'datetime.datetime' object has no attribute 'strip'
2025-07-10 16:35:23,530 - src.processing.batch_processor - ERROR - File: batch_processor.py - File: batch_processor.py - File: batch_processor.py - File: batch_processor.py - File: batch_processor.py - [ERROR] Failed to process 7579E18A-2439-4BFF-A0F7-96B110FB3A40.xml: Failed to save invoice to database
2025-07-10 16:35:23,577 - src.data.database - ERROR - File: database.py - File: database.py - File: database.py - File: database.py - File: database.py - Database session error: 'datetime.datetime' object has no attribute 'strip'
2025-07-10 16:35:23,579 - src.processing.batch_processor - ERROR - File: batch_processor.py - File: batch_processor.py - File: batch_processor.py - File: batch_processor.py - File: batch_processor.py - Database save failed: 'datetime.datetime' object has no attribute 'strip'
2025-07-10 16:35:23,580 - src.processing.batch_processor - ERROR - File: batch_processor.py - File: batch_processor.py - File: batch_processor.py - File: batch_processor.py - File: batch_processor.py - [ERROR] Failed to process 7CB73D45-AF0A-434F-A1E0-902AC8314AC1.xml: Failed to save invoice to database
2025-07-10 16:35:32,771 - src.data.database - ERROR - File: database.py - File: database.py - File: database.py - File: database.py - File: database.py - Database session error: 'datetime.datetime' object has no attribute 'strip'
2025-07-10 16:35:32,771 - src.processing.batch_processor - ERROR - File: batch_processor.py - File: batch_processor.py - File: batch_processor.py - File: batch_processor.py - File: batch_processor.py - Database save failed: 'datetime.datetime' object has no attribute 'strip'
2025-07-10 16:35:32,771 - src.processing.batch_processor - ERROR - File: batch_processor.py - File: batch_processor.py - File: batch_processor.py - File: batch_processor.py - File: batch_processor.py - [ERROR] Failed to process 7D2019DB-CD61-4600-8F65-DD44ADF4FC0E.xml: Failed to save invoice to database
2025-07-10 16:35:34,104 - src.data.database - ERROR - File: database.py - File: database.py - File: database.py - File: database.py - File: database.py - Database session error: 'datetime.datetime' object has no attribute 'strip'
2025-07-10 16:35:34,117 - src.processing.batch_processor - ERROR - File: batch_processor.py - File: batch_processor.py - File: batch_processor.py - File: batch_processor.py - File: batch_processor.py - Database save failed: 'datetime.datetime' object has no attribute 'strip'
2025-07-10 16:35:34,118 - src.processing.batch_processor - ERROR - File: batch_processor.py - File: batch_processor.py - File: batch_processor.py - File: batch_processor.py - File: batch_processor.py - [ERROR] Failed to process 7E6332A9-BF15-4F9F-BE4F-CEADDF154AD7.xml: Failed to save invoice to database
2025-07-10 16:35:36,867 - src.data.database - ERROR - File: database.py - File: database.py - File: database.py - File: database.py - File: database.py - Database session error: 'datetime.datetime' object has no attribute 'strip'
2025-07-10 16:35:36,867 - src.processing.batch_processor - ERROR - File: batch_processor.py - File: batch_processor.py - File: batch_processor.py - File: batch_processor.py - File: batch_processor.py - Database save failed: 'datetime.datetime' object has no attribute 'strip'
2025-07-10 16:35:36,868 - src.processing.batch_processor - ERROR - File: batch_processor.py - File: batch_processor.py - File: batch_processor.py - File: batch_processor.py - File: batch_processor.py - [ERROR] Failed to process 8AC2BFA4-8362-4291-B692-9C2D450198E4.xml: Failed to save invoice to database
2025-07-10 16:35:47,840 - src.data.database - ERROR - File: database.py - File: database.py - File: database.py - File: database.py - File: database.py - Database session error: 'datetime.datetime' object has no attribute 'strip'
2025-07-10 16:35:47,840 - src.processing.batch_processor - ERROR - File: batch_processor.py - File: batch_processor.py - File: batch_processor.py - File: batch_processor.py - File: batch_processor.py - Database save failed: 'datetime.datetime' object has no attribute 'strip'
2025-07-10 16:35:47,843 - src.processing.batch_processor - ERROR - File: batch_processor.py - File: batch_processor.py - File: batch_processor.py - File: batch_processor.py - File: batch_processor.py - [ERROR] Failed to process 8CCD00E8-8EAC-4926-BE8F-0B57C8856E84.xml: Failed to save invoice to database
2025-07-10 16:35:48,112 - src.data.database - ERROR - File: database.py - File: database.py - File: database.py - File: database.py - File: database.py - Database session error: 'datetime.datetime' object has no attribute 'strip'
2025-07-10 16:35:48,113 - src.processing.batch_processor - ERROR - File: batch_processor.py - File: batch_processor.py - File: batch_processor.py - File: batch_processor.py - File: batch_processor.py - Database save failed: 'datetime.datetime' object has no attribute 'strip'
2025-07-10 16:35:48,113 - src.processing.batch_processor - ERROR - File: batch_processor.py - File: batch_processor.py - File: batch_processor.py - File: batch_processor.py - File: batch_processor.py - [ERROR] Failed to process 9B316DDF-0827-4012-B8E8-9C08161BF41B.xml: Failed to save invoice to database
2025-07-10 16:35:49,380 - src.data.database - ERROR - File: database.py - File: database.py - File: database.py - File: database.py - File: database.py - Database session error: 'datetime.datetime' object has no attribute 'strip'
2025-07-10 16:35:49,380 - src.processing.batch_processor - ERROR - File: batch_processor.py - File: batch_processor.py - File: batch_processor.py - File: batch_processor.py - File: batch_processor.py - Database save failed: 'datetime.datetime' object has no attribute 'strip'
2025-07-10 16:35:49,382 - src.processing.batch_processor - ERROR - File: batch_processor.py - File: batch_processor.py - File: batch_processor.py - File: batch_processor.py - File: batch_processor.py - [ERROR] Failed to process ACF5E9D9-459A-485E-A8DF-9A2E14F03941.xml: Failed to save invoice to database
2025-07-10 16:35:51,154 - src.data.database - ERROR - File: database.py - File: database.py - File: database.py - File: database.py - File: database.py - Database session error: 'datetime.datetime' object has no attribute 'strip'
2025-07-10 16:35:51,156 - src.processing.batch_processor - ERROR - File: batch_processor.py - File: batch_processor.py - File: batch_processor.py - File: batch_processor.py - File: batch_processor.py - Database save failed: 'datetime.datetime' object has no attribute 'strip'
2025-07-10 16:35:51,158 - src.processing.batch_processor - ERROR - File: batch_processor.py - File: batch_processor.py - File: batch_processor.py - File: batch_processor.py - File: batch_processor.py - [ERROR] Failed to process C8E39A35-3357-4C8F-AF22-534AFE703FEA.xml: Failed to save invoice to database
2025-07-10 16:35:54,630 - src.data.database - ERROR - File: database.py - File: database.py - File: database.py - File: database.py - File: database.py - Database session error: 'datetime.datetime' object has no attribute 'strip'
2025-07-10 16:35:54,630 - src.processing.batch_processor - ERROR - File: batch_processor.py - File: batch_processor.py - File: batch_processor.py - File: batch_processor.py - File: batch_processor.py - Database save failed: 'datetime.datetime' object has no attribute 'strip'
2025-07-10 16:35:54,632 - src.processing.batch_processor - ERROR - File: batch_processor.py - File: batch_processor.py - File: batch_processor.py - File: batch_processor.py - File: batch_processor.py - [ERROR] Failed to process E3BAA208-BB42-49C5-9E72-D7702308F471.xml: Failed to save invoice to database
2025-07-10 16:35:56,312 - src.data.database - ERROR - File: database.py - File: database.py - File: database.py - File: database.py - File: database.py - Database session error: 'datetime.datetime' object has no attribute 'strip'
2025-07-10 16:35:56,313 - src.processing.batch_processor - ERROR - File: batch_processor.py - File: batch_processor.py - File: batch_processor.py - File: batch_processor.py - File: batch_processor.py - Database save failed: 'datetime.datetime' object has no attribute 'strip'
2025-07-10 16:35:56,313 - src.processing.batch_processor - ERROR - File: batch_processor.py - File: batch_processor.py - File: batch_processor.py - File: batch_processor.py - File: batch_processor.py - [ERROR] Failed to process EFCD0679-9CE8-400D-8869-9B9D2C51DE62.xml: Failed to save invoice to database
2025-07-11 16:38:34,545 - src.data.database - ERROR - File: database.py - File: database.py - File: database.py - File: database.py - File: database.py - Database session error: 37 values for 38 columns
2025-07-11 16:38:34,551 - src.processing.batch_processor - ERROR - File: batch_processor.py - File: batch_processor.py - File: batch_processor.py - File: batch_processor.py - File: batch_processor.py - [PURCHASE_DETAILS] Failed to save to purchase_details table: 37 values for 38 columns
2025-07-11 16:38:46,456 - src.data.database - ERROR - File: database.py - File: database.py - File: database.py - File: database.py - File: database.py - Database session error: 37 values for 38 columns
2025-07-11 16:38:46,457 - src.processing.batch_processor - ERROR - File: batch_processor.py - File: batch_processor.py - File: batch_processor.py - File: batch_processor.py - File: batch_processor.py - [PURCHASE_DETAILS] Failed to save to purchase_details table: 37 values for 38 columns
2025-07-11 16:38:48,745 - src.data.database - ERROR - File: database.py - File: database.py - File: database.py - File: database.py - File: database.py - Database session error: 37 values for 38 columns
2025-07-11 16:38:48,746 - src.processing.batch_processor - ERROR - File: batch_processor.py - File: batch_processor.py - File: batch_processor.py - File: batch_processor.py - File: batch_processor.py - [PURCHASE_DETAILS] Failed to save to purchase_details table: 37 values for 38 columns
2025-07-11 16:38:54,288 - src.data.database - ERROR - File: database.py - File: database.py - File: database.py - File: database.py - File: database.py - Database session error: 37 values for 38 columns
2025-07-11 16:38:54,289 - src.processing.batch_processor - ERROR - File: batch_processor.py - File: batch_processor.py - File: batch_processor.py - File: batch_processor.py - File: batch_processor.py - [PURCHASE_DETAILS] Failed to save to purchase_details table: 37 values for 38 columns
2025-07-11 16:39:03,418 - src.data.database - ERROR - File: database.py - File: database.py - File: database.py - File: database.py - File: database.py - Database session error: 37 values for 38 columns
2025-07-11 16:39:03,420 - src.processing.batch_processor - ERROR - File: batch_processor.py - File: batch_processor.py - File: batch_processor.py - File: batch_processor.py - File: batch_processor.py - [PURCHASE_DETAILS] Failed to save to purchase_details table: 37 values for 38 columns
2025-07-11 16:39:05,708 - src.data.database - ERROR - File: database.py - File: database.py - File: database.py - File: database.py - File: database.py - Database session error: 37 values for 38 columns
2025-07-11 16:39:05,711 - src.processing.batch_processor - ERROR - File: batch_processor.py - File: batch_processor.py - File: batch_processor.py - File: batch_processor.py - File: batch_processor.py - [PURCHASE_DETAILS] Failed to save to purchase_details table: 37 values for 38 columns
2025-07-11 16:39:06,485 - src.data.database - ERROR - File: database.py - File: database.py - File: database.py - File: database.py - File: database.py - Database session error: 37 values for 38 columns
2025-07-11 16:39:06,487 - src.processing.batch_processor - ERROR - File: batch_processor.py - File: batch_processor.py - File: batch_processor.py - File: batch_processor.py - File: batch_processor.py - [PURCHASE_DETAILS] Failed to save to purchase_details table: 37 values for 38 columns
2025-07-11 16:39:09,428 - src.data.database - ERROR - File: database.py - File: database.py - File: database.py - File: database.py - File: database.py - Database session error: 37 values for 38 columns
2025-07-11 16:39:09,430 - src.processing.batch_processor - ERROR - File: batch_processor.py - File: batch_processor.py - File: batch_processor.py - File: batch_processor.py - File: batch_processor.py - [PURCHASE_DETAILS] Failed to save to purchase_details table: 37 values for 38 columns
2025-07-11 16:39:15,188 - src.data.database - ERROR - File: database.py - File: database.py - File: database.py - File: database.py - File: database.py - Database session error: 37 values for 38 columns
2025-07-11 16:39:15,189 - src.processing.batch_processor - ERROR - File: batch_processor.py - File: batch_processor.py - File: batch_processor.py - File: batch_processor.py - File: batch_processor.py - [PURCHASE_DETAILS] Failed to save to purchase_details table: 37 values for 38 columns
2025-07-11 16:39:21,567 - src.data.database - ERROR - File: database.py - File: database.py - File: database.py - File: database.py - File: database.py - Database session error: 37 values for 38 columns
2025-07-11 16:39:21,568 - src.processing.batch_processor - ERROR - File: batch_processor.py - File: batch_processor.py - File: batch_processor.py - File: batch_processor.py - File: batch_processor.py - [PURCHASE_DETAILS] Failed to save to purchase_details table: 37 values for 38 columns
2025-07-11 16:39:28,612 - src.data.database - ERROR - File: database.py - File: database.py - File: database.py - File: database.py - File: database.py - Database session error: 37 values for 38 columns
2025-07-11 16:39:28,613 - src.processing.batch_processor - ERROR - File: batch_processor.py - File: batch_processor.py - File: batch_processor.py - File: batch_processor.py - File: batch_processor.py - [PURCHASE_DETAILS] Failed to save to purchase_details table: 37 values for 38 columns
2025-07-11 16:39:30,438 - src.data.database - ERROR - File: database.py - File: database.py - File: database.py - File: database.py - File: database.py - Database session error: 37 values for 38 columns
2025-07-11 16:39:30,439 - src.processing.batch_processor - ERROR - File: batch_processor.py - File: batch_processor.py - File: batch_processor.py - File: batch_processor.py - File: batch_processor.py - [PURCHASE_DETAILS] Failed to save to purchase_details table: 37 values for 38 columns
2025-07-11 16:39:36,232 - src.data.database - ERROR - File: database.py - File: database.py - File: database.py - File: database.py - File: database.py - Database session error: 37 values for 38 columns
2025-07-11 16:39:36,235 - src.processing.batch_processor - ERROR - File: batch_processor.py - File: batch_processor.py - File: batch_processor.py - File: batch_processor.py - File: batch_processor.py - [PURCHASE_DETAILS] Failed to save to purchase_details table: 37 values for 38 columns
2025-07-11 16:39:40,021 - src.data.database - ERROR - File: database.py - File: database.py - File: database.py - File: database.py - File: database.py - Database session error: 37 values for 38 columns
2025-07-11 16:39:40,022 - src.processing.batch_processor - ERROR - File: batch_processor.py - File: batch_processor.py - File: batch_processor.py - File: batch_processor.py - File: batch_processor.py - [PURCHASE_DETAILS] Failed to save to purchase_details table: 37 values for 38 columns
2025-07-11 16:39:50,991 - src.data.database - ERROR - File: database.py - File: database.py - File: database.py - File: database.py - File: database.py - Database session error: 37 values for 38 columns
2025-07-11 16:39:50,992 - src.processing.batch_processor - ERROR - File: batch_processor.py - File: batch_processor.py - File: batch_processor.py - File: batch_processor.py - File: batch_processor.py - [PURCHASE_DETAILS] Failed to save to purchase_details table: 37 values for 38 columns
